Workbook

Sheet מלאי לא תקין
A1: Plant | B1: Storage Location | C1: Material | D1: Material Description | E1: Batch | F1: Base Unit of Measure | G1: Old material number | H1: Unrestricted | I1: Restricted-Use Stock | J1: Blocked | K1: Transit and Transfer | L1: HU change | M1: UD Code | N1: UD Description | O1: Date of Manufacture | P1: SLED/BBD | Q1: Batch remarks | R1: Batch indicator | S1: QM Notification | T1: Last Insp lot UD remarks | U1: Containers ID (Creation Date) | V1: Delivery for batch | W1: UD code for delivery | X1: Pack order QC status | Y1: Delivery Ref document | Z1: Delivery Ref document item | AA1: Supplier Batch | AB1: Last Goods Receipt | AC1: Batch process order | AD1: Batch creation date | AE1: Central Item Code | AF1: שיוך למתקן/משפחה | AG1: סה"כ לא תקין | AH1: חיבור מתקן והחלטת שימוש
AF2: =VLOOKUP(C2,'גיליון דאטה להכל'!A:H,5,0) -> #N/A | AG2: =I2+H2 -> 0 | AH2: =_xlfn.CONCAT(AF2,N2) -> #N/A
AF3: =VLOOKUP(C3,'גיליון דאטה להכל'!A:H,5,0) -> #N/A | AG3: =I3+H3 -> 0 | AH3: =_xlfn.CONCAT(AF3,N3) -> #N/A
AF4: =VLOOKUP(C4,'גיליון דאטה להכל'!A:H,5,0) -> #N/A | AG4: =I4+H4 -> 0 | AH4: =_xlfn.CONCAT(AF4,N4) -> #N/A
AF5: =VLOOKUP(C5,'גיליון דאטה להכל'!A:H,5,0) -> #N/A | AG5: =I5+H5 -> 0 | AH5: =_xlfn.CONCAT(AF5,N5) -> #N/A
AF6: =VLOOKUP(C6,'גיליון דאטה להכל'!A:H,5,0) -> #N/A | AG6: =I6+H6 -> 0 | AH6: =_xlfn.CONCAT(AF6,N6) -> #N/A
AF7: =VLOOKUP(C7,'גיליון דאטה להכל'!A:H,5,0) -> #N/A | AG7: =I7+H7 -> 0 | AH7: =_xlfn.CONCAT(AF7,N7) -> #N/A
AF8: =VLOOKUP(C8,'גיליון דאטה להכל'!A:H,5,0) -> #N/A | AG8: =I8+H8 -> 0 | AH8: =_xlfn.CONCAT(AF8,N8) -> #N/A
AF9: =VLOOKUP(C9,'גיליון דאטה להכל'!A:H,5,0) -> #N/A | AG9: =I9+H9 -> 0 | AH9: =_xlfn.CONCAT(AF9,N9) -> #N/A
AF10: =VLOOKUP(C10,'גיליון דאטה להכל'!A:H,5,0) -> #N/A | AG10: =I10+H10 -> 0 | AH10: =_xlfn.CONCAT(AF10,N10) -> #N/A
AF11: =VLOOKUP(C11,'גיליון דאטה להכל'!A:H,5,0) -> #N/A | AG11: =I11+H11 -> 0 | AH11: =_xlfn.CONCAT(AF11,N11) -> #N/A
AF12: =VLOOKUP(C12,'גיליון דאטה להכל'!A:H,5,0) -> #N/A | AG12: =I12+H12 -> 0 | AH12: =_xlfn.CONCAT(AF12,N12) -> #N/A
AF13: =VLOOKUP(C13,'גיליון דאטה להכל'!A:H,5,0) -> #N/A | AG13: =I13+H13 -> 0 | AH13: =_xlfn.CONCAT(AF13,N13) -> #N/A
... AF63: =VLOOKUP(C63,'גיליון דאטה להכל'!A:H,5,0) -> #N/A | AG63: =I63+H63 -> 0 | AH63: =_xlfn.CONCAT(AF63,N63) -> #N/A
AF64: =VLOOKUP(C64,'גיליון דאטה להכל'!A:H,5,0) -> #N/A | AG64: =I64+H64 -> 0 | AH64: =_xlfn.CONCAT(AF64,N64) -> #N/A | AU64: 0
AF65: =VLOOKUP(C65,'גיליון דאטה להכל'!A:H,5,0) -> #N/A | AG65: =I65+H65 -> 0 | AH65: =_xlfn.CONCAT(AF65,N65) -> #N/A
AF66: =VLOOKUP(C66,'גיליון דאטה להכל'!A:H,5,0) -> #N/A | AG66: =I66+H66 -> 0 | AH66: =_xlfn.CONCAT(AF66,N66) -> #N/A
AF67: =VLOOKUP(C67,'גיליון דאטה להכל'!A:H,5,0) -> #N/A | AG67: =I67+H67 -> 0 | AH67: =_xlfn.CONCAT(AF67,N67) -> #N/A
AF68: =VLOOKUP(C68,'גיליון דאטה להכל'!A:H,5,0) -> #N/A | AG68: =I68+H68 -> 0 | AH68: =_xlfn.CONCAT(AF68,N68) -> #N/A
AF69: =VLOOKUP(C69,'גיליון דאטה להכל'!A:H,5,0) -> #N/A | AG69: =I69+H69 -> 0 | AH69: =_xlfn.CONCAT(AF69,N69) -> #N/A
AF70: =VLOOKUP(C70,'גיליון דאטה להכל'!A:H,5,0) -> #N/A | AG70: =I70+H70 -> 0 | AH70: =_xlfn.CONCAT(AF70,N70) -> #N/A
AF71: =VLOOKUP(C71,'גיליון דאטה להכל'!A:H,5,0) -> #N/A | AG71: =I71+H71 -> 0 | AH71: =_xlfn.CONCAT(AF71,N71) -> #N/A
AF72: =VLOOKUP(C72,'גיליון דאטה להכל'!A:H,5,0) -> #N/A | AG72: =I72+H72 -> 0 | AH72: =_xlfn.CONCAT(AF72,N72) -> #N/A
AF73: =VLOOKUP(C73,'גיליון דאטה להכל'!A:H,5,0) -> #N/A | AG73: =I73+H73 -> 0 | AH73: =_xlfn.CONCAT(AF73,N73) -> #N/A
AF74: =VLOOKUP(C74,'גיליון דאטה להכל'!A:H,5,0) -> #N/A | AG74: =I74+H74 -> 0 | AH74: =_xlfn.CONCAT(AF74,N74) -> #N/A
AF75: =VLOOKUP(C75,'גיליון דאטה להכל'!A:H,5,0) -> #N/A | AG75: =I75+H75 -> 0 | AH75: =_xlfn.CONCAT(AF75,N75) -> #N/A
AF76: =VLOOKUP(C76,'גיליון דאטה להכל'!A:H,5,0) -> #N/A | AG76: =I76+H76 -> 0 | AH76: =_xlfn.CONCAT(AF76,N76) -> #N/A
... AF1318: =VLOOKUP(C1318,'גיליון דאטה להכל'!A:H,5,0) -> #N/A | AG1318: =I1318+H1318 -> 0 | AH1318: =_xlfn.CONCAT(AF1318,N1318) -> #N/A
AG1319: =I1319+H1319 -> 0 | AH1319: =_xlfn.CONCAT(AF1319,N1319)
AG1320: =I1320+H1320 -> 0 | AH1320: =_xlfn.CONCAT(AF1320,N1320)

Sheet מתקן ופירוט לצורך בדיקה
A3: תוויות שורה | B3: סכום של Delivered quantity (GMEIN)
A4: (ריק)
A5: 1528 | B5: 40100
A6: 1543 | B6: 9600
A7: 1541 | B7: 12540
A8: 1519 | B8: 67660
A9: 1540 | B9: 18000
A10: 1124 | B10: 11770
A11: 1523 | B11: 19000
A12: 1141 | B12: 14792
A13: 1525 | B13: 21800
A14: 1140 | B14: 2100
A15: 1542 | B15: 24000
A16: סכום כולל | B16: 241362

Sheet מתקן
A3: תוויות שורה | B3: סכום של Delivered quantity (GMEIN)
A4: (ריק)
A5: 1528 | B5: 40100
A6: 1543 | B6: 9600
A7: 1541 | B7: 12540
A8: 1519 | B8: 67660
A9: 1540 | B9: 18000
A10: 1124 | B10: 11770
A11: 1523 | B11: 19000
A12: 1141 | B12: 14792
A13: 1525 | B13: 21800
A14: 1140 | B14: 2100
A15: 1542 | B15: 24000
A16: סכום כולל | B16: 241362

Sheet פיוות ביצוע יומי
A3: סכום של Delivered quantity (GMEIN) | B3: תוויות עמודה
A4: תוויות שורה | B4: 45962 | C4: 45963 | D4: 45964 | E4: 45965 | F4: 45966 | G4: 45967 | H4: 45968 | I4: 45969 | J4: 45970 | K4: 45971 | L4: 45972 | M4: 45973 | N4: 45974 | O4: 45975 | P4: 45976 | Q4: סכום כולל
A5: 1 | B5: 9216 | Q5: 9216
A6: 5 | B6: 12000 | C6: 17040 | D6: 31200 | E6: 13200 | F6: 31900 | G6: 21000 | H6: 48000 | I6: 26700 | J6: 35400 | K6: 50400 | L6: 58200 | M6: 48000 | N6: 2000 | O6: 15600 | P6: 9600 | Q6: 420240
A7: 10 | C7: 10800 | I7: 21000 | O7: 12000 | P7: 24000 | Q7: 67800
A8: 19 | B8: 8160 | C8: 20640 | D8: 66240 | E8: 14640 | F8: 37440 | G8: 10800 | H8: 5040 | I8: 5760 | J8: 11520 | K8: 23280 | L8: 44160 | M8: 73320 | N8: 51300 | O8: 55065 | P8: 67660 | Q8: 495025
A9: 23 | B9: 7000 | C9: 60080 | D9: 33000 | E9: 16840 | F9: 17000 | G9: 14840 | H9: 24400 | I9: 53400 | J9: 47550 | K9: 12000 | L9: 12000 | M9: 34960 | N9: 24000 | O9: 30960 | P9: 19000 | Q9: 407030
A10: 28 | B10: 33000 | C10: 40000 | D10: 14000 | E10: 70400 | F10: 57800 | G10: 35200 | H10: 62632 | I10: 51600 | J10: 73800 | K10: 62600 | L10: 34800 | M10: 66600 | N10: 49400 | O10: 46900 | P10: 38700 | Q10: 737432
A11: 24F | B11: 11920 | C11: 4000 | D11: 8000 | F11: 8000 | G11: 7000 | H11: 5000 | I11: 6450 | J11: 2000 | K11: 15000 | L11: 14000 | M11: 7000 | O11: 8000 | P11: 11770 | Q11: 108140
A12: GALIGAN | C12: 3300 | F12: 1650 | G12: 1650 | H12: 1650 | J12: 1650 | K12: 1650 | M12: 3300 | N12: 1650 | Q12: 16500
A13: EC 25 | B13: 33000 | C13: 22650 | D13: 8000 | F13: 9600 | G13: 8000 | I13: 7000 | J13: 7500 | O13: 9400 | P13: 6800 | Q13: 111950
A14: DELTA DAMASCON | E14: 7920 | J14: 3600 | O14: 6480 | Q14: 18000
A15: DIURON | C15: 59400 | D15: 21500 | E15: 14100 | F15: 27900 | G15: 21000 | J15: 58200 | K15: 31200 | M15: 44100 | N15: 21000 | O15: 26100 | P15: 6600 | Q15: 331100
A16: LINURON | D16: 3600 | Q16: 3600
A17: KROVAR | C17: 3000 | D17: 2000 | E17: 1500 | P17: 1500 | Q17: 8000
A18: NANA | B18: 3832 | C18: 11170 | D18: 3951 | E18: 3878 | F18: 3888 | G18: 8095 | H18: 3906 | I18: 7937 | J18: 4881 | K18: 12129 | L18: 3880 | M18: 8174 | N18: 3852 | O18: 3600 | P18: 7425 | Q18: 90598
A19: סכום כולל | B19: 118128 | C19: 252080 | D19: 191491 | E19: 142478 | F19: 195178 | G19: 127585 | H19: 150628 | I19: 179847 | J19: 246101 | K19: 208259 | L19: 167040 | M19: 285454 | N19: 153202 | O19: 214105 | P19: 193055 | Q19: 2824631

Sheet משפחת מוצר (2)
A2: Storage Location | B2: (הכל)
A4: תוויות שורה | B4: Material | C4: סכום של Delivered quantity (GMEIN)
A5: (ריק) | B5: (ריק)
A6: 45976 | B6: 10000000442 | C6: 47500
B7: 30000000076 | C7: 6600
B8: 30000000084 | C8: 1500
B9: 30000000113 | C9: 9900
B10: 50000000049 | C10: 3000
B11: 50000000056 | C11: 1740
B12: 50000000072 | C12: 2100
B13: 50000000077 | C13: 8820
B14: 50000000108 | C14: 15000
B15: 10000000401 | C15: 20160
B16: 20000000683 | C16: 6800
B17: 30000000097 | C17: 5115
B18: 10000002484 | C18: 24000
... B29: 20000000805 | C29: 8700
A30: סכום כולל | C30: 241362

Sheet לעדכן בסינתזה דאטה אריזה 42+24
A1: Local Item Code | B1: Production Line Descr | C1: גודל אריזה | D1: משפחה לתכנון | E1: צריך להסיר מהמדידה | F1: Formulation Code | G1: Description | H1: Capacity | I1: *Production Line Code | J1: Formulation Res
A2: 10000000160 | B2: 10\20 liter | C2: 20 | D2: #N/A | E2: #N/A | F2: EC | G2: ACTC770 EC ACETOGAN 768 EC - 20 20LT ZA | H2: 0 | I2: AGAN-42-P-04 | J2: 42
A3: 10000000161 | B3: 10\20 liter | C3: 10 | D3: #N/A | E3: #N/A | F3: EC | G3: ACTC900 EC Acierto 900 EC 10L 10LT NZ | H3: 0 | I3: AGAN-42-P-04 | J3: 42
A4: 10000000162 | B4: 10\20 liter | C4: 20 | D4: #N/A | E4: #N/A | F4: EC | G4: ACTC900 EC Acetogan EC - 20l 20LT UA | H4: 0 | I4: AGAN-42-P-04 | J4: 42
A5: 10000000163 | B5: 10\20 liter | C5: 20 | D5: #N/A | E5: #N/A | F5: EC | G5: ACTC900 EC Acetogan 900 EC - 20l 20LT ZA | H5: 0 | I5: AGAN-42-P-04 | J5: 42
A6: 10000000164 | B6: 10\20 liter | C6: 20 | D6: #N/A | E6: #N/A | F6: EC | G6: ACTC900 EC Acierto 900 EC 20L 20LT NZ | H6: 0 | I6: AGAN-42-P-04 | J6: 42
A7: 10000000165 | C7: 23 | G7: ACTC900 EC Acierto 900 EC 200L 200LT NZ | J7: 23
A8: 10000000169 | B8: 10 | C8: 10 | D8: #N/A | E8: #N/A | F8: EC | G8: ACLN600 SC COLT 10LT 10LT FR | H8: 8 | I8: AGAN-23-F-07 | J8: 42
A9: 10000000170 | C9: 10 | D9: #N/A | E9: #N/A | F9: EC | G9: ACLN600 SC PAPEL 10 LT 10LT FR | H9: 8 | I9: AGAN-23-F-08 | J9: 42
A10: 10000000179 | B10: 10\20 liter | C10: 10 | D10: AMETRYN | E10: Class 3 | F10: EC | G10: ACTC880 EC Acenit A EC - 10l 10LT UA | H10: 0 | I10: AGAN-42-P-04 | J10: 42
A11: 10000000180 | C11: 19 | G11: AMTR800 WG AMETREX 80 WG 500 KG 500KG MX | J11: 19
A12: 10000000181 | C12: 19 | G12: AMTR800 WG Ametryne 80% WG [500 500KG IN | J12: 19
A13: 10000000182 | C13: 19 | G13: AMTR800 WG AMETREX 80WG CENAM 15KG CAM | J13: 19
A14: 10000000185 | C14: 19 | G14: AMTR800 WG Ametrex WG 15KG 15KG AU | J14: 19
A15: 10000000186 | C15: 19 | G15: AMTR800 WG AMETRYN 80 WG VIETNAM 15KG VN | J15: 19
A16: 10000000191 | B16: 1 liter | C16: 1 liter | D16: #N/A | E16: #N/A | F16: EC | G16: ALCL480 EC Alanex 48 EC x 1 Lt 1LT CAM | H16: 0 | I16: AGAN-42-P-02 | J16: 42
A17: 10000000192 | B17: 10\20 liter | C17: 5 | D17: #N/A | E17: #N/A | F17: EC | G17: ALCL480 EC Alanex 10 Liter 10LT IL | H17: 0 | I17: AGAN-42-P-04 | J17: 42
A18: 10000000193 | B18: 10\20 liter | C18: 20 | D18: ATRAZINE | E18: Class 2 | G18: ALCL480 MCB Cyclone 20L 20LT NZ | H18: 0 | I18: AGAN-42-P-04 | J18: 42
A19: 10000000194 | B19: 10\20 liter | C19: 20 | D19: #N/A | E19: #N/A | F19: SC | G19: AMTR500 SC Ametrex 50 SC x 20 L 20LT CAM | H19: 0 | I19: AGAN-42-P-04 | J19: 42
A20: 10000000195 | B20: 10\20 liter | C20: 20 | D20: ATRAZINE | E20: Class 2 | F20: SC | G20: AMTR500 SC Ametrex 50 SC x 20 Lt 20LT DO | H20: 0 | I20: AGAN-42-P-04 | J20: 42
A21: 10000000196 | B21: 10\20 liter | C21: 20 | D21: #N/A | E21: #N/A | F21: SC | G21: AMTR500 SC AMETREX 50 SC Chinese 20LT DO | H21: 0 | I21: AGAN-42-P-04 | J21: 42
A22: 10000000213 | B22: 5 lIter | C22: 1 | D22: #N/A | E22: #N/A | F22: SC | G22: AMTR250+ARZN250 SC ATRAMET COMBI 5LT ET | H22: 0 | I22: AGAN-42-P-03 | J22: 42
A23: 10000000219 | B23: 5 lIter | C23: 5 | D23: #N/A | E23: #N/A | F23: SC | G23: ARZN500 SC Atranex 5 L 5LT IL | H23: 0 | I23: AGAN-42-P-03 | J23: 42
A24: 10000000229 | B24: 5 lIter | C24: 5 | G24: BRXL240 EC Bromotril 5 L 5LT IL | J24: 42
A25: 10000000245 | B25: 1 liter | C25: 1 | D25: #N/A | E25: #N/A | F25: SC | G25: BFNX480 SC VALLEY Lt. 1 1LT IT | H25: 0 | I25: AGAN-42-P-02 | J25: 42
A26: 10000000246 | B26: 1 liter | C26: 1 | D26: #N/A | E26: #N/A | F26: SC | G26: BFNX480 SC FOXPRO Lt. 1 1LT IT | H26: 0 | I26: AGAN-42-P-02 | J26: 42
A27: 10000000247 | B27: 5 lIter | C27: 5 lIter | D27: #N/A | E27: #N/A | F27: SC | G27: BFNX480 SC FOX (4 X 5L) 5LT GB | H27: 0 | I27: AGAN-42-P-03 | J27: 42
A28: 10000000248 | B28: 5 lIter | C28: 5 | D28: #N/A | E28: #N/A | F28: SC | G28: BFNX480 SC MODOWN 4X5L ROMANIA 5LT RO | H28: 0 | I28: AGAN-42-P-03 | J28: 42
A29: 10000000249 | B29: 5 lIter | C29: 5 | D29: #N/A | E29: #N/A | F29: SC | G29: BFNX480 SC Fox 5LT DE | H29: 0 | I29: AGAN-42-P-03 | J29: 42
A30: 10000000250 | B30: 5 lIter | C30: 5 lIter | D30: #N/A | E30: #N/A | F30: SC | G30: BFNX480 SC Fox 480 SC NL [5.000] 5LT NL | H30: 0 | I30: AGAN-42-P-03 | J30: 42
A31: 10000000251 | B31: 5 lIter | C31: 5 | D31: #N/A | E31: #N/A | F31: SC | G31: BFNX480 SC FOX 5 LT 5LT FR | H31: 0 | I31: AGAN-42-P-03 | J31: 42
A32: 10000000252 | B32: 5 lIter | C32: 5 lIter | D32: #N/A | E32: #N/A | F32: SC | G32: BFNX480 SC Fox 480 SC 5LT BE | H32: 0 | I32: AGAN-42-P-03 | J32: 42
A33: 10000000253 | C33: 23 | G33: CLTD120 EC AKODIM 12 200LT MOR 200LT MA | J33: 23
A34: 10000000261 | B34: 10\20 liter | C34: 1 | D34: #N/A | E34: #N/A | F34: ME | G34: BNTZ480+CLMZ50 ME Eventus ME 10LT UA | H34: 0 | I34: AGAN-42-P-04 | J34: 42
A35: 10000000262 | B35: 10\20 liter | C35: 1 | D35: #N/A | E35: #N/A | F35: EC | G35: BRXL327+MCPA351 EC BADGE 20LT KE 20LT KE | H35: 0 | I35: AGAN-42-P-04 | J35: 42
A36: 10000000263 | B36: 5 lIter | C36: 5 lIter | D36: #N/A | E36: #N/A | F36: EC | G36: BRXL240 EC Adama Essentials Bromo 5LT AR | H36: 0 | I36: AGAN-42-P-03 | J36: 42
A37: 10000000270 | C37: 23 | G37: CLMZ480 EC KALIF 200L KENYA 200LT KE | J37: 23
A38: 10000000271 | B38: 5 lIter | C38: 5 lIter | D38: #N/A | E38: #N/A | F38: EC | G38: BRXL240 EC Bromotril 5 L 5LT IL | H38: 0 | I38: AGAN-42-P-03 | J38: 42
A39: 10000000272 | B39: 5 lIter | C39: 5 lIter | D39: #N/A | E39: #N/A | F39: SC | G39: BRXL250 SC BROMOTRIL 250 5L BEL 5LT BE | H39: 0 | I39: AGAN-42-P-03 | J39: 42
A40: 10000000273 | B40: 5 lIter | C40: 5 lIter | D40: #N/A | E40: #N/A | F40: SC | G40: BRXL250 SC Bromotril 250 SC NL [5 5LT NL | H40: 0 | I40: AGAN-42-P-03 | J40: 42
...

Sheet 42
A1: Storage Location | B1: (ריק)
A3: תוויות שורה | B3: סכום של Delivered quantity (GMEIN)
A4: #N/A
A5: (ריק)
A6: (ריק)
A7: (ריק)
A8: סכום כולל

Sheet Sum
A1: =TODAY() -> 46236 | B1: Production Report Aug 2026
A2: 1 | B2: Capacity | C2: Plan | D2: Production | E2: % Achievement | F2: Req. t/d | G2: Req. t/d | H2: Last day | I2: Last day | J2: Need days | K2: Adjusted Req. t/d | L2: Adjusted Req. t/d | M2: Actual t/d | N2: %Rate | O2: %Rate | Q2: New Adherence | R2: Recycling Plan | S2: Recycled | T2: For Packing | U2: Restricted - recycling | V2: Restricted – risk for disposal | W2: Contaminated Internal Use | X2: Remarks | Z2: Month progress | AA2: Month progress | AB2: start date | AC2: end date | AE2: Production days remaining | AF2: production days | AG2: Reduced working days | AH2: ability | AP2: % | AQ2: AVERAGE | AR2: 46235
A3: EC(25,23) | C3: =C4+C21 -> 650 | D3: =D4+D21 -> 44.456 | E3: =IFERROR(D3/C3,0) -> 0.068393846 | G3: =C3/(AC3-AB3+1) -> 20.967742 | I3: =I4+I21 -> 44.456 | L3: =IF(AD3>0,(C3-D3)/(AC3-$A$2),0) -> 20.1848 | M3: =D3/$A$2 -> 44.456 | O3: =IFERROR(E3/AA3,0) -> 1.9150277 | Y3: 28 | AA3: =IF(AB3=1,$A$2/Y3,($A$2-AB3)/(Y3-AB3)) -> 0.035714286 | AB3: 1 | AC3: 31 | AD3: =($A$2-(AB3-1))*(C3-D3) -> 605.544 | AI3: 3920 | AJ3: =D3 -> 44.456 | AK3: =4062-1400 -> 2662 | AL3: =AI3-AJ3-AK3 -> 1213.544 | AM3: =SUM(AK3+AJ3)/AI3 -> 0.69042245
A4: EC (23) | B4: 1000 | C4: 500 | D4: =sumif!C36 -> 44.456 | E4: =IFERROR(D4/C4,0) -> 0.088912 | F4: =C4/J4 -> 53 | G4: =(C4-D4)/(AC4-$A$2) -> 15.1848 | H4: =I4 -> 44.456 | I4: =sumif!B36 -> 44.456 | J4: =C4/AH4 -> 9.4339623 | K4: =(C4-D4)/(J4-AF4) -> 48.287664 | L4: =IFERROR((C4-D4)/AE4,0) -> 17.520923 | M4: =D4/$A$2 -> 44.456 | N4: =IFERROR(E4/Z4,0) -> 0 | O4: =IFERROR(E4/AA4,0) -> -0.15357527 | Q4: =MAX((1-ABS((D4-C4)/C4)),0) -> 0.088912 | R4: 12 | S4: =C4*O4 -> -76.787636 | T4: =sumif!E75/1000 -> 0 | U4: =sumif!F75/1000 -> 0 | Y4: 31 | Z4: =AF4/J4 -> 0 | AA4: =IF(AB4=1,$A$2/Y4,($A$2-AB4)/(Y4-AB4)) -> -0.57894737 | AB4: 12 | AC4: 31 | AD4: =($A$2-(AB4-1))*(C4-D4) -> -4555.44 | AE4: 26 | AF4: ='[1]EC (23)'!F1 -> 0 | AG4: =3*2 -> 6 | AH4: 53 | AP4: =IF(AQ4/G4,AQ4/G4,0) -> 2.9276645 | AQ4: =AVERAGE(AR4:AV4) -> 44.456 | AR4: 44.456
A5: LQ pack (42) | D5: =sumif!C37 -> 65 | E5: =IFERROR(D5/C5,0) -> 0 | F5: =C5/J5 -> #DIV/0! | G5: =(C5-D5)/(AC5-$A$2) -> -2.1666667 | H5: =I5 -> 65 | I5: =sumif!B37 -> 65 | J5: =C5/AH5 -> 0 | K5: =(C5-D5)/(J5-AF5) -> #DIV/0! | L5: =IFERROR((C5-D5)/AE5,0) -> -2.1666667 | M5: =D5/$A$2 -> 65 | N5: =IFERROR(E5/Z5,0) -> 0 | O5: =IFERROR(E5/AA5,0) -> 0 | Q5: =MAX((1-ABS((D5-C5)/C5)),0) -> #DIV/0! | S5: =C5*O5 -> 0 | T5: =sumif!E76 -> 0 | U5: =sumif!F76 -> 0 | Y5: 19 | Z5: =AF5/J5 -> #DIV/0! | AA5: =IF(AB5=1,$A$2/Y5,($A$2-AB5)/(Y5-AB5)) -> -1.5714286 | AB5: 12 | AC5: 31 | AD5: =($A$2-(AB5-1))*(C5-D5) -> 650 | AE5: 30 | AF5: ='[1]EC (23)'!F2 -> 0 | AG5: =3*2 -> 6 | AH5: 54 | AI5: 8100 | AJ5: =D5 -> 65 | AK5: =4613-C5 -> 4613 | AL5: =AI5-AK5 -> 3487 | AM5: =SUM(AK5+AJ5)/AI5 -> 0.57753086 | AP5: =IF(AQ5/G5,AQ5/G5,0) -> -30 | AQ5: =AVERAGE(AR5:AV5) -> 65 | AR5: 65
A6: Shaked iso (42+23) | B6: 240 | C6: 0 | D6: =sumif!C34 -> 0 | E6: =IFERROR(D6/C6,0) -> 0 | F6: =C6/J6 -> #DIV/0! | G6: =(C6-D6)/(AC6-$A$2) -> 0 | H6: =I6 -> 0 | I6: =sumif!B34 -> 0 | J6: =C6/AH6 -> 0 | K6: =(C6-D6)/(J6-AF6) -> #DIV/0! | L6: =IFERROR((C6-D6)/AE6,0) -> 0 | M6: =D6/$A$2 -> 0 | N6: =IFERROR(E6/Z6,0) -> 0 | O6: =IFERROR(E6/AA6,0) -> 0 | Q6: =MAX((1-ABS((D6-C6)/C6)),0) -> #DIV/0! | S6: =C6*O6 -> 0 | T6: =sumif!E215/1000 -> 0 | U6: =sumif!F215/1000 -> 0 | Y6: 19 | Z6: =AF6/J6 -> #DIV/0! | AA6: =IF(AB6=1,$A$2/Y6,($A$2-AB6)/(Y6-AB6)) -> -1.5714286 | AB6: 12 | AC6: 31 | AD6: =($A$2-(AB6-1))*(C6-D6) -> 0 | AE6: 26 | AF6: ='[1]EC (23)'!F3 -> 0 | AG6: =3*2 -> 6 | AH6: 55 | AP6: =IF(AQ6/G6,AQ6/G6,0) -> #DIV/0! | AQ6: =AVERAGE(AR6:AV6) -> 0 | AR6: 0
A7: Galigan iso (42) | B7: 120 | C7: 144 | D7: =sumif!C42 -> 0 | E7: =IFERROR(D7/C7,0) -> 0 | F7: =C7/J7 -> #DIV/0! | G7: =(C7-D7)/(AC7-$A$2) -> 4.8 | I7: =sumif!B42 -> 0 | L7: =IFERROR((C7-D7)/AE7,0) -> 5.5384615 | M7: =D7/$A$2 -> 0 | N7: =IFERROR(E7/Z7,0) -> 0 | O7: =IFERROR(E7/AA7,0) -> 0 | Q7: =MAX((1-ABS((D7-C7)/C7)),0) -> 0 | S7: =C7*O7 -> 0 | T7: =sumif!E155/1000 -> 0 | U7: =sumif!F155/1000 -> 0 | Y7: 19 | Z7: =AF7/J7 -> #DIV/0! | AA7: =IF(AB7=1,$A$2/Y7,($A$2-AB7)/(Y7-AB7)) -> -1.5714286 | AB7: 12 | AC7: 31 | AD7: =($A$2-(AB7-1))*(C7-D7) -> -1440 | AE7: 26 | AF7: ='[1]EC (23)'!F4 -> 0 | AG7: =3*2 -> 6 | AH7: 56 | AP7: =IF(AQ7/G7,AQ7/G7,0) -> 0 | AQ7: =AVERAGE(AR7:AV7) -> 0 | AR7: 0
A8: LQ 1lt (42) | B8: =18*30 -> 540 | C8: 20 | D8: =sumif!C30 -> 0 | E8: =IFERROR(D8/C8,0) -> 0 | F8: =C8/J8 -> 3 | G8: =(C8-D8)/(AC8-$A$2) -> 0.66666667 | H8: =I8 -> 0 | I8: =sumif!B30 -> 0 | J8: =C8/AH8 -> 6.6666667 | K8: =(C8-D8)/(J8-AF8) -> 3 | L8: =IFERROR((C8-D8)/AE8,0) -> 0.76923077 | M8: =D8/$A$2 -> 0 | N8: =IFERROR(E8/Z8,0) -> 0 | O8: =IFERROR(E8/AA8,0) -> 0 | Q8: =MAX((1-ABS((D8-C8)/C8)),0) -> 0 | S8: =C8*O8 -> 0 | T8: =sumif!E55/1000 -> 0 | U8: =sumif!F55/1000 -> 0 | Y8: 31 | Z8: =AF8/J8 -> 0 | AA8: =IF(AB8=1,$A$2/Y8,($A$2-AB8)/(Y8-AB8)) -> -0.57894737 | AB8: 12 | AC8: 31 | AD8: =($A$2-(AB8-1))*(C8-D8) -> -200 | AE8: 26 | AF8: ='[1]1 lt '!F1 -> 0 | AH8: 3 | AP8: =IF(AQ8/G8,AQ8/G8,0) -> 0 | AQ8: =AVERAGE(AR8:AV8) -> 0 | AR8: 0
A9: LQ 5 lt (42) | B9: =45*30 -> 1350 | C9: 250 | D9: =sumif!C29-D11 -> 0 | E9: =IFERROR(D9/C9,0) -> 0 | F9: =C9/J9 -> 45 | G9: =(C9-D9)/(AC9-$A$2) -> 8.3333333 | H9: =I9 -> 0 | I9: =sumif!B29-I11 -> 0 | J9: =C9/AH9 -> 5.5555556 | K9: =(C9-D9)/(J9-AF9) -> 45 | L9: =IFERROR((C9-D9)/AE9,0) -> 9.6153846 | M9: =D9/$A$2 -> 0 | N9: =IFERROR(E9/Z9,0) -> 0 | O9: =IFERROR(E9/AA9,0) -> 0 | Q9: =MAX((1-ABS((D9-C9)/C9)),0) -> 0 | S9: =C9*O9 -> 0 | T9: =sumif!E60/1000 -> 0 | U9: =sumif!F60/1000 -> 0 | Y9: 31 | Z9: =AF9/J9 -> 0 | AA9: =IF(AB9=1,$A$2/Y9,($A$2-AB9)/(Y9-AB9)) -> -0.57894737 | AB9: 12 | AC9: 31 | AD9: =($A$2-(AB9-1))*(C9-D9) -> -2500 | AE9: 26 | AF9: ='[1]5 lt'!F1 -> 0 | AH9: 45 | AP9: =IF(AQ9/G9,AQ9/G9,0) -> 0 | AQ9: =AVERAGE(AR9:AV9) -> 0 | AR9: 0
A10: LQ 10/20 lt (42) | B10: =45*30 -> 1350 | C10: 362 | D10: =sumif!C33 -> 0 | E10: =IFERROR(D10/C10,0) -> 0 | F10: =C10/J10 -> 45 | G10: =(C10-D10)/(AC10-$A$2) -> 12.066667 | H10: =I10 -> 0 | I10: =sumif!B33 -> 0 | J10: =C10/AH10 -> 8.0444444 | K10: =(C10-D10)/(J10-AF10) -> 45 | L10: =IFERROR((C10-D10)/AE10,0) -> 13.923077 | M10: =D10/$A$2 -> 0 | N10: =IFERROR(E10/Z10,0) -> 0 | O10: =IFERROR(E10/AA10,0) -> 0 | Q10: =MAX((1-ABS((D10-C10)/C10)),0) -> 0 | S10: =C10*O10 -> 0 | T10: =sumif!E65/1000 -> 0 | U10: =sumif!F65/1000 -> 0 | Y10: 31 | Z10: =AF10/J10 -> 0 | AA10: =IF(AB10=1,$A$2/Y10,($A$2-AB10)/(Y10-AB10)) -> -0.57894737 | AB10: 12 | AC10: 31 | AD10: =($A$2-(AB10-1))*(C10-D10) -> -3620 | AE10: 26 | AF10: ='[1]10 lt'!F6 -> 0 | AH10: 45 | AP10: =IF(AQ10/G10,AQ10/G10,0) -> 0 | AQ10: =AVERAGE(AR10:AV10) -> 0 | AR10: 0
A11: MCW | C11: 600 | D11: =sumif!C43 -> 0 | E11: =IFERROR(D11/C11,0) -> 0 | I11: =sumif!B43 -> 0 | O11: =IFERROR(E11/AA11,0) -> 0 | Q11: =MAX((1-ABS((D11-C11)/C11)),0) -> 0 | S11: =C11*O11 -> 0 | Y11: 31 | AB11: 12 | AC11: 31 | AE11: 26 | AQ11: =AVERAGE(AR11:AV11) -> 0 | AR11: 0
A12: LQ 43 | B12: =26*22 -> 572 | D12: =sumif!C44 -> 0 | E12: =IFERROR(D12/C12,0) -> 0 | F12: =C12/J12 -> #DIV/0! | G12: =(C12-D12)/(AC12-$A$2) -> 0 | I12: =sumif!B44 -> 0 | L12: =IFERROR((C12-D12)/AE12,0) -> 0 | M12: =D12/$A$2 -> 0 | O12: =IFERROR(E12/AA12,0) -> 0 | Q12: =MAX((1-ABS((D12-C12)/C12)),0) -> #DIV/0! | S12: =C12*O12 -> 0 | X12: ממתין לאישור הפעלה | Y12: 31 | Z12: =AF12/J12 -> #DIV/0! | AA12: =IF(AB12=1,$A$2/Y12,($A$2-AB12)/(Y12-AB12)) -> -0.57894737 | AB12: 12 | AC12: 31 | AD12: =($A$2-(AB12-1))*(C12-D12) -> 0 | AE12: 26 | AF12: ='[1]10 lt'!F7 -> 0 | AH12: 46 | AP12: =IF(AQ12/G12,AQ12/G12,0) -> #DIV/0! | AQ12: =AVERAGE(AR12:AV12) -> 0 | AR12: 0
A13: SC (28) | B13: 1600 | C13: 1550 | D13: =sumif!C37-D14 -> 65 | E13: =IFERROR(D13/C13,0) -> 0.041935484 | F13: =C13/J13 -> 76 | G13: =(C13-D13)/(AC13-$A$2) -> 49.5 | H13: =I13 -> 65 | I13: =sumif!B37-I14 -> 65 | J13: =C13/AH13 -> 20.394737 | K13: =(C13-D13)/(J13-AF13) -> 72.812903 | L13: =IFERROR((C13-D13)/AE13,0) -> 57.115385 | M13: =D13/$A$2 -> 65 | N13: =O13 -> -0.072434018 | O13: =IFERROR(E13/AA13,0) -> -0.072434018 | Q13: =MAX((1-ABS((D13-C13)/C13)),0) -> 0.041935484 | R13: 180 | S13: =C13*O13 -> -112.27273 | T13: =sumif!E90/1000 -> 0 | U13: =sumif!F90/1000 -> 0 | Y13: 31 | Z13: =AA13 -> -0.57894737 | AA13: =IF(AB13=1,$A$2/Y13,($A$2-AB13)/(Y13-AB13)) -> -0.57894737 | AB13: 12 | AC13: 31 | AD13: =($A$2-(AB13-1))*(C13-D13) -> -14850 | AE13: 26 | AH13: =19*4 -> 76 | AI13: 5887 | AJ13: =D13 -> 65 | AK13: =5265-1600 -> 3665 | AL13: =AI13-AK13 -> 2222 | AM13: =SUM(AK13+AJ13)/AI13 -> 0.63359946 | AP13: =IF(AQ13/G13,AQ13/G13,0) -> 1.3131313 | AQ13: =AVERAGE(AR13:AV13) -> 65 | AR13: 65
A14: NH | C14: 500 | D14: =sumif!C38 -> 0 | E14: =IFERROR(D14/C14,0) -> 0 | G14: =(C14-D14)/(AC14-$A$2) -> 16.666667 | I14: =sumif!B38 -> 0 | L14: =IFERROR((C14-D14)/AE14,0) -> 0 | M14: =D14/$A$2 -> 0 | O14: =IFERROR(E14/AA14,0) -> 0 | Q14: =MAX((1-ABS((D14-C14)/C14)),0) -> 0 | X14: תגבור פירמול בנאות חובב | Y14: 31 | AB14: 12 | AC14: 31 | AQ14: =AVERAGE(AR14:AV14) -> 0 | AR14: 0
A15: WG 19 | D15: =D16+D17 -> 0 | E15: =IFERROR(D15/C15,0) -> 0 | F15: =C15/(AC15-AB15+1) -> 0 | G15: =(C15-D15)/(AC15-$A$2) -> 0 | H15: =H16+H17 -> 0 | I15: =I16+I17 -> 0 | J15: =C15/AH15 -> #DIV/0! | K15: =(C15-D15)/AE15 -> 0 | L15: =IFERROR((C15-D15)/AE15,0) -> 0 | M15: =D15/$A$2 -> 0 | N15: =O15 -> 0 | O15: =IFERROR(E15/AA15,0) -> 0 | Q15: =MAX((1-ABS((D15-C15)/C15)),0) -> #DIV/0! | S15: =C15*O15 -> 0 | T15: =sumif!E83 -> 0 | U15: =sumif!F83 -> 0 | Y15: 31 | Z15: =AA15 -> -0.57894737 | AA15: =IF(AB15=1,$A$2/Y15,($A$2-AB15)/(Y15-AB15)) -> -0.57894737 | AB15: 12 | AC15: 31 | AD15: =($A$2-(AB15-1))*(C15-D15) -> 0 | AE15: 26 | AP15: =IF(AQ15/G15,AQ15/G15,0) -> #DIV/0! | AQ15: =AVERAGE(AR15:AV15) -> 0 | AR15: 0
A16: WG (19) | B16: 1500 | C16: 480 | D16: 0 | E16: =IFERROR(D16/C16,0) -> 0 | F16: =C16/(AC16-AB16+1) -> 24 | G16: =(C16-D16)/(AC16-$A$2) -> 16 | H16: =I16 -> 0 | I16: 0 | J16: =C16/AH16 -> 22.857143 | K16: =(C16-D16)/AE16 -> 18.461538 | L16: =IFERROR((C16-D16)/AE16,0) -> 18.461538 | M16: =D16/$A$2 -> 0 | N16: =O16 -> 0 | O16: =IFERROR(E16/AA16,0) -> 0 | Q16: =MAX((1-ABS((D16-C16)/C16)),0) -> 0 | R16: 60 | S16: =C16*O16 -> 0 | T16: =sumif!E50/1000 -> 0 | U16: =sumif!F50/1000 -> 0 | Y16: 31 | Z16: =AA16 -> -0.57894737 | AA16: =IF(AB16=1,$A$2/Y16,($A$2-AB16)/(Y16-AB16)) -> -0.57894737 | AB16: 12 | AC16: 31 | AD16: =($A$2-(AB16-1))*(C16-D16) -> -4800 | AE16: 26 | AH16: 21 | AI16: 3750 | AJ16: =D16 -> 0 | AK16: =4232-1200 -> 3032 | AL16: =AI16-AK16 -> 718 | AM16: =SUM(AK16+AJ16)/AI16 -> 0.80853333 | AP16: =IF(AQ16/G16,AQ16/G16,0) -> 0 | AQ16: =AVERAGE(AR16:AV16) -> 0 | AR16: 0
A17: WG small packs (19) | B17: 750 | C17: 150 | D17: 0 | E17: =IFERROR(D17/C17,0) -> 0 | F17: =C17/(AC17-AB17+1) -> 7.5 | G17: =(C17-D17)/(AC17-$A$2) -> 5 | H17: =I17 -> 0 | I17: 0 | J17: =C17/AH17 -> 7.1428571 | K17: =(C17-D17)/AE17 -> 5.7692308 | L17: =IFERROR((C17-D17)/AE17,0) -> 5.7692308 | M17: =D17/$A$2 -> 0 | N17: =O17 -> 0 | O17: =IFERROR(E17/AA17,0) -> 0 | Q17: =MAX((1-ABS((D17-C17)/C17)),0) -> 0 | S17: =C17*O17 -> 0 | T17: =sumif!E85/1000 -> 0 | U17: =sumif!F85/1000 -> 0 | Y17: 31 | Z17: =AA17 -> -0.57894737 | AA17: =IF(AB17=1,$A$2/Y17,($A$2-AB17)/(Y17-AB17)) -> -0.57894737 | AB17: 12 | AC17: 31 | AD17: =($A$2-(AB17-1))*(C17-D17) -> -1500 | AE17: 26 | AH17: 21 | AI17: 2955 | AJ17: =D17 -> 0 | AK17: =2167-500 -> 1667 | AL17: =AI17-AK17 -> 1288 | AM17: =SUM(AK17+AJ17)/AI17 -> 0.5641286 | AP17: =IF(AQ17/G17,AQ17/G17,0) -> 0 | AQ17: =AVERAGE(AR17:AV17) -> 0 | AR17: 0
A18: 24F128 | B18: 180 | C18: 146 | D18: =sumif!C40 -> 0 | E18: =IFERROR(D18/C18,0) -> 0 | G18: =(C18-D18)/(AC18-$A$2) -> 4.8666667 | I18: =sumif!B40 -> 0 | O18: =IFERROR(E18/AA18,0) -> 0 | Q18: =MAX((1-ABS((D18-C18)/C18)),0) -> 0 | S18: =C18*O18 -> 0 | Y18: 31 | AA18: =IF(AB18=1,$A$2/Y18,($A$2-AB18)/(Y18-AB18)) -> -0.57894737 | AB18: 12 | AC18: 31 | AD18: =($A$2-(AB18-1))*(C18-D18) -> -1460 | AP18: =IF(AQ18/G18,AQ18/G18,0) -> 0 | AQ18: =AVERAGE(AR18:AV18) -> 0 | AR18: 0
A19: 24F | B19: 180 | C19: 180 | D19: =sumif!C39 -> 5.37 | E19: =IFERROR(D19/C19,0) -> 0.029833333 | F19: =C19/(AC19-AB19+1) -> 9 | G19: =IFERROR((C19-D19)/(AC19-$A$2),0) -> 5.821 | H19: =I19 -> 5.37 | I19: =sumif!B39 -> 5.37 | J19: =C19/AH19 -> 25.714286 | K19: =(C19-D19)/AE19 -> 6.7165385 | L19: =IFERROR((C19-D19)/AE19,0) -> 6.7165385 | M19: =D19/$A$2 -> 5.37 | N19: =O19 -> -0.051530303 | O19: =IFERROR(E19/AA19,0) -> -0.051530303 | Q19: =MAX((1-ABS((D19-C19)/C19)),0) -> 0.029833333 | S19: =C19*O19 -> -9.2754545 | T19: =sumif!E80/1000 -> 0 | U19: =sumif!F80/1000 -> 0 | Y19: 31 | Z19: =AA19 -> -0.57894737 | AA19: =IF(AB19=1,$A$2/Y19,($A$2-AB19)/(Y19-AB19)) -> -0.57894737 | AB19: 12 | AC19: 31 | AD19: =($A$2-(AB19-1))*(C19-D19) -> -1746.3 | AE19: 26 | AH19: 7 | AI19: 510 | AJ19: =D19 -> 5.37 | AK19: 256 | AL19: =AI19-AK19 -> 254 | AM19: =SUM(AK19+AJ19)/AI19 -> 0.5124902 | AP19: =IFERROR(IF(AQ19/G19,AQ19/G19,0),0) -> 0.9225219 | AQ19: =AVERAGE(AR19:AV19) -> 5.37 | AR19: 5.37
A20: LRH Pack(24) | B20: 420 | C20: 0 | D20: =sumif!C41 -> 0 | E20: =IFERROR(D20/C20,0) -> 0 | F20: =C20/(AC20-AB20+1) -> 0 | G20: =(C20-D20)/(AC20-$A$2) -> 0 | H20: =I20 -> 0 | I20: =sumif!B41 -> 0 | K20: =(C20-D20)/AE20 -> 0 | L20: =IFERROR((C20-D20)/AE20,0) -> 0 | M20: =D20/$A$2 -> 0 | N20: =O20 -> 0 | O20: =IFERROR(E20/AA20,0) -> 0 | Q20: =MAX((1-ABS((D20-C20)/C20)),0) -> #DIV/0! | S20: =C20*O20 -> 0 | T20: =sumif!E85/1000 -> 0 | U20: =sumif!F85/1000 -> 0 | X20: אריזה במתקן 42 | Y20: 31 | Z20: =AA20 -> -0.57894737 | AA20: =IF(AB20=1,$A$2/Y20,($A$2-AB20)/(Y20-AB20)) -> -0.57894737 | AB20: 12 | AC20: 31 | AD20: =($A$2-(AB20-1))*(C20-D20) -> 0 | AE20: 26 | AI20: 518 | AJ20: =D20 -> 0 | AK20: 174 | AL20: =AI20-AK20 -> 344 | AM20: =SUM(AK20+AJ20)/AI20 -> 0.33590734 | AP20: =IF(AQ20/G20,AQ20/G20,0) -> #DIV/0! | AQ20: =AVERAGE(AR20:AV20) -> 0 | AR20: 0
A21: EC (25) | B21: =730+180 -> 910 | C21: 150 | D21: =sumif!C2 -> 0 | E21: =IFERROR(D21/C21,0) -> 0 | F21: =C21/(AC21-AB21+1) -> 7.5 | G21: =(C21-D21)/(AC21-$A$2) -> 5 | H21: =I21 -> 0 | I21: =sumif!B2 -> 0 | K21: =(C21-D21)/AE21 -> 5.7692308 | L21: =IFERROR((C21-D21)/AE21,0) -> 5.7692308 | M21: =D21/$A$2 -> 0 | N21: =O21 -> 0 | O21: =IFERROR(E21/AA21,0) -> 0 | Q21: =MAX((1-ABS((D21-C21)/C21)),0) -> 0 | R21: 50 | S21: =C21*O21 -> 0 | T21: =sumif!E130/1000 -> 0 | U21: =sumif!F130/1000 -> 0 | Y21: 31 | Z21: =AA21 -> -0.57894737 | AA21: =IF(AB21=1,$A$2/Y21,($A$2-AB21)/(Y21-AB21)) -> -0.57894737 | AB21: 12 | AC21: 31 | AD21: =($A$2-(AB21-1))*(C21-D21) -> -1500 | AE21: 26 | AP21: =IF(AQ21/G21,AQ21/G21,0) -> 0 | AQ21: =AVERAGE(AR21:AV21) -> 0 | AR21: 0
A22: Diuron (40) | B22: 900 | C22: 550 | D22: =sumif!C14 -> 26.4 | E22: =IFERROR(D22/C22,0) -> 0.048 | F22: =C22/(AC22-AB22+1) -> 27.5 | G22: =(C22-D22)/(AC22-$A$2) -> 17.453333 | H22: =I22 -> 26.4 | I22: =sumif!B14 -> 26.4 | K22: =(C22-D22)/AE22 -> 20.138462 | L22: =IFERROR((C22-D22)/AE22,0) -> 20.138462 | M22: =D22/$A$2 -> 26.4 | N22: =O22 -> -0.082909091 | O22: =IFERROR(E22/AA22,0) -> -0.082909091 | Q22: =MAX((1-ABS((D22-C22)/C22)),0) -> 0.048 | S22: =C22*O22 -> -45.6 | T22: =sumif!E125/1000 -> 0 | U22: =sumif!F125/1000 -> 0 | X22: מחסור ב DMA | Y22: 31 | Z22: =AA22 -> -0.57894737 | AA22: =IF(AB22=1,$A$2/Y22,($A$2-AB22)/(Y22-AB22)) -> -0.57894737 | AB22: 12 | AC22: 31 | AD22: =($A$2-(AB22-1))*(C22-D22) -> -5236 | AE22: 26 | AI22: 2470 | AJ22: =D22 -> 26.4 | AK22: 1098 | AL22: =AI22-AK22 -> 1372 | AM22: =SUM(AK22+AJ22)/AI22 -> 0.45522267 | AP22: =IF(AQ22/G22,AQ22/G22,0) -> 1.512605 | AQ22: =AVERAGE(AR22:AV22) -> 26.4 | AR22: 26.4
A23: Tolurex (40) | B23: 330 | C23: 260 | D23: =sumif!C15 -> 9.9 | E23: =IFERROR(D23/C23,0) -> 0.038076923 | F23: =C23/(AC23-AB23+1) -> 13 | G23: =(C23-D23)/(AC23-$A$2) -> 8.3366667 | H23: =I23 -> 9.9 | I23: =sumif!B15 -> 9.9 | K23: =(C23-D23)/AE23 -> 9.6192308 | L23: =IFERROR((C23-D23)/AE23,0) -> 9.6192308 | M23: =D23/$A$2 -> 9.9 | N23: =O23 -> -0.065769231 | O23: =IFERROR(E23/AA23,0) -> -0.065769231 | Q23: =MAX((1-ABS((D23-C23)/C23)),0) -> 0.038076923 | R23: 25 | S23: =C23*O23 -> -17.1 | T23: =sumif!E110/1000 -> 0 | U23: =sumif!F110/1000 -> 0 | Y23: 31 | Z23: =AA23 -> -0.57894737 | AA23: =IF(AB23=1,$A$2/Y23,($A$2-AB23)/(Y23-AB23)) -> -0.57894737 | AB23: 12 | AC23: 31 | AD23: =($A$2-(AB23-1))*(C23-D23) -> -2501 | AE23: 26 | AP23: =IF(AQ23/G23,AQ23/G23,0) -> 1.187525 | AQ23: =AVERAGE(AR23:AV23) -> 9.9 | AR23: 9.9
A24: Cottonex (25,40) | B24: 330 | C24: 0 | D24: =sumif!C22 -> 0 | E24: =IFERROR(D24/C24,0) -> 0 | F24: =C24/(AC24-AB24+1) -> 0 | G24: =(C24-D24)/(AC24-$A$2) -> 0 | H24: =I24 -> 0 | I24: =sumif!B22 -> 0 | K24: =(C24-D24)/AE24 -> 0 | L24: =IFERROR((C24-D24)/AE24,0) -> 0 | M24: =D24/$A$2 -> 0 | N24: =O24 -> 0 | O24: =IFERROR(E24/AA24,0) -> 0 | Q24: =MAX((1-ABS((D24-C24)/C24)),0) -> #DIV/0! | S24: =C24*O24 -> 0 | T24: =sumif!E145/1000 -> 0 | U24: =sumif!F145/1000 -> 0 | Y24: 31 | Z24: =AA24 -> -0.57894737 | AA24: =IF(AB24=1,$A$2/Y24,($A$2-AB24)/(Y24-AB24)) -> -0.57894737 | AB24: 12 | AC24: 31 | AD24: =($A$2-(AB24-1))*(C24-D24) -> 0 | AE24: 26 | AP24: =IF(AQ24/G24,AQ24/G24,0) -> #DIV/0! | AQ24: =AVERAGE(AR24:AV24) -> 0 | AR24: 0
A25: CS (25,40) | B25: 180 | C25: 78 | D25: =sumif!C6 -> 0 | E25: =IFERROR(D25/C25,0) -> 0 | F25: =C25/(AC25-AB25+1) -> 3.9 | G25: =(C25-D25)/(AC25-$A$2) -> 2.6 | H25: =I25 -> 0 | I25: =sumif!B6 -> 0 | K25: =(C25-D25)/AE25 -> 3 | L25: =IFERROR((C25-D25)/AE25,0) -> 3 | M25: =D25/$A$2 -> 0 | N25: =O25 -> 0 | O25: =IFERROR(E25/AA25,0) -> 0 | Q25: =MAX((1-ABS((D25-C25)/C25)),0) -> 0 | R25: 12 | S25: =C25*O25 -> 0 | T25: =sumif!E115/1000 -> 0 | U25: =sumif!F115/1000 -> 0 | Y25: 31 | Z25: =AA25 -> -0.57894737 | AA25: =IF(AB25=1,$A$2/Y25,($A$2-AB25)/(Y25-AB25)) -> -0.57894737 | AB25: 12 | AC25: 31 | AD25: =($A$2-(AB25-1))*(C25-D25) -> -780 | AE25: 26 | AI25: 384 | AJ25: =D25 -> 0 | AK25: 118 | AL25: =AI25-AK25 -> 266 | AM25: =SUM(AK25+AJ25)/AI25 -> 0.30729167 | AP25: =IF(AQ25/G25,AQ25/G25,0) -> 0 | AQ25: =AVERAGE(AR25:AV25) -> 0 | AR25: 0
A26: WP (40) | B26: 100 | C26: 0 | D26: =sumif!C7 -> 0 | E26: =IFERROR(D26/C26,0) -> 0 | F26: =C26/(AC26-AB26+1) -> 0 | G26: =(C26-D26)/(AC26-$A$2) -> 0 | H26: =I26 -> 0 | I26: =sumif!B7 -> 0 | K26: =(C26-D26)/AE26 -> 0 | L26: =IFERROR((C26-D26)/AE26,0) -> 0 | M26: =D26/$A$2 -> 0 | N26: =O26 -> 0 | O26: =IFERROR(E26/AA26,0) -> 0 | Q26: =MAX((1-ABS((D26-C26)/C26)),0) -> #DIV/0! | S26: =C26*O26 -> 0 | T26: =sumif!E226/1000 -> 0 | U26: =sumif!F226/1000 -> 0 | Y26: 31 | Z26: =AA26 -> -0.57894737 | AA26: =IF(AB26=1,$A$2/Y26,($A$2-AB26)/(Y26-AB26)) -> -0.57894737 | AB26: 12 | AC26: 31 | AD26: =($A$2-(AB26-1))*(C26-D26) -> 0 | AE26: 26 | AI26: 145 | AJ26: =D26 -> 0 | AK26: 66 | AL26: =AI26-AK26 -> 79 | AM26: =SUM(AK26+AJ26)/AI26 -> 0.45517241 | AP26: =IF(AQ26/G26,AQ26/G26,0) -> #DIV/0! | AQ26: =AVERAGE(AR26:AV26) -> 0 | AR26: 0
A27: Bromacil (25,40) | B27: 105 | C27: 40 | D27: =sumif!C13 -> 2.1 | E27: =IFERROR(D27/C27,0) -> 0.0525 | F27: =C27/(AC27-AB27+1) -> 2 | G27: =(C27-D27)/(AC27-$A$2) -> 1.2633333 | H27: =I27 -> 2.1 | I27: =sumif!B13 -> 2.1 | K27: =(C27-D27)/AE27 -> 1.4576923 | L27: =IFERROR((C27-D27)/AE27,0) -> 1.4576923 | M27: =D27/$A$2 -> 2.1 | N27: =O27 -> -0.090681818 | O27: =IFERROR(E27/AA27,0) -> -0.090681818 | Q27: =MAX((1-ABS((D27-C27)/C27)),0) -> 0.0525 | S27: =C27*O27 -> -3.6272727 | T27: =sumif!E105/1000 -> 0 | U27: =sumif!F105/1000 -> 0 | Y27: 31 | Z27: =AA27 -> -0.57894737 | AA27: =IF(AB27=1,$A$2/Y27,($A$2-AB27)/(Y27-AB27)) -> -0.57894737 | AB27: 12 | AC27: 31 | AD27: =($A$2-(AB27-1))*(C27-D27) -> -379 | AE27: 26 | AI27: 232 | AJ27: =D27 -> 2.1 | AK27: 115 | AL27: =AI27-AK27 -> 117 | AM27: =SUM(AK27+AJ27)/AI27 -> 0.50474138 | AP27: =IF(AQ27/G27,AQ27/G27,0) -> 1.6622691 | AQ27: =AVERAGE(AR27:AV27) -> 2.1 | AR27: 2.1
A28: Krovar (40) | B28: 60 | C28: 0 | D28: =sumif!C12 -> 0 | E28: =IFERROR(D28/C28,0) -> 0 | F28: =C28/(AC28-AB28+1) -> 0 | G28: =(C28-D28)/(AC28-$A$2) -> 0 | H28: =I28 -> 0 | I28: =sumif!B12 -> 0 | K28: =(C28-D28)/AE28 -> 0 | L28: =IFERROR((C28-D28)/AE28,0) -> 0 | M28: =D28/$A$2 -> 0 | N28: =O28 -> 0 | O28: =IFERROR(E28/AA28,0) -> 0 | Q28: =MAX((1-ABS((D28-C28)/C28)),0) -> #DIV/0! | S28: =C28*O28 -> 0 | T28: =sumif!E170/1000 -> 0 | U28: =sumif!F170/1000 -> 0 | Y28: 31 | Z28: =AA28 -> -0.57894737 | AA28: =IF(AB28=1,$A$2/Y28,($A$2-AB28)/(Y28-AB28)) -> -0.57894737 | AB28: 12 | AC28: 31 | AD28: =($A$2-(AB28-1))*(C28-D28) -> 0 | AE28: 26 | AK28: 0 | AP28: =IF(AQ28/G28,AQ28/G28,0) -> #DIV/0! | AQ28: =AVERAGE(AR28:AV28) -> 0 | AR28: 0
A29: Galigan (25,40) | B29: 45 | C29: 20 | D29: =sumif!C9 -> 0 | E29: =IFERROR(D29/C29,0) -> 0 | F29: =C29/(AC29-AB29+1) -> 1 | G29: =(C29-D29)/(AC29-$A$2) -> 0.66666667 | H29: =I29 -> 0 | I29: =sumif!B9 -> 0 | K29: =(C29-D29)/AE29 -> 0.76923077 | L29: =IFERROR((C29-D29)/AE29,0) -> 0.76923077 | M29: =D29/$A$2 -> 0 | N29: =O29 -> 0 | O29: =IFERROR(E29/AA29,0) -> 0 | Q29: =MAX((1-ABS((D29-C29)/C29)),0) -> 0 | S29: =C29*O29 -> 0 | T29: =sumif!E161/1000 -> 0 | U29: =sumif!F161/1000 -> 0 | X29: חוסר TRIFLUOROMETHYL PHENOL | Y29: 31 | Z29: =AA29 -> -0.57894737 | AA29: =IF(AB29=1,$A$2/Y29,($A$2-AB29)/(Y29-AB29)) -> -0.57894737 | AB29: 12 | AC29: 31 | AD29: =($A$2-(AB29-1))*(C29-D29) -> -200 | AE29: 26 | AI29: 116 | AJ29: =D29 -> 0 | AK29: 36 | AL29: =AI29-AK29 -> 80 | AM29: =SUM(AK29+AJ29)/AI29 -> 0.31034483 | AP29: =IF(AQ29/G29,AQ29/G29,0) -> 0 | AQ29: =AVERAGE(AR29:AV29) -> 0 | AR29: 0
A30: Propa Premix (25,40) | B30: 330 | D30: =sumif!C19 -> 0 | E30: =IFERROR(D30/C30,0) -> 0 | F30: =C30/(AC30-AB30+1) -> 0 | G30: =(C30-D30)/(AC30-$A$2) -> 0 | H30: =I30 -> 0 | I30: =sumif!B19 -> 0 | K30: =(C30-D30)/AE30 -> 0 | L30: =IFERROR((C30-D30)/AE30,0) -> 0 | M30: =D30/$A$2 -> 0 | N30: =O30 -> 0 | O30: =IFERROR(E30/AA30,0) -> 0 | Q30: =MAX((1-ABS((D30-C30)/C30)),0) -> #DIV/0! | S30: =C30*O30 -> 0 | T30: =sumif!E196/1000 -> 0 | U30: =sumif!F196/1000 -> 0 | Y30: 31 | Z30: =AA30 -> -0.57894737 | AA30: =IF(AB30=1,$A$2/Y30,($A$2-AB30)/(Y30-AB30)) -> -0.57894737 | AB30: 12 | AC30: 31 | AD30: =($A$2-(AB30-1))*(C30-D30) -> 0 | AE30: 26 | AI30: 704 | AJ30: =D30 -> 0 | AK30: 0 | AL30: =AI30-AK30 -> 704 | AM30: =SUM(AK30+AJ30)/AI30 -> 0 | AP30: =IF(AQ30/G30,AQ30/G30,0) -> #DIV/0! | AQ30: =AVERAGE(AR30:AV30) -> 0 | AR30: 0
A31: Propa Melt (25,40) | B31: 300 | C31: 0 | D31: =sumif!C18 -> 0 | E31: =IFERROR(D31/C31,0) -> 0 | F31: =C31/(AC31-AB31+1) -> 0 | G31: =(C31-D31)/(AC31-$A$2) -> 0 | H31: =I31 -> 0 | I31: =sumif!B18 -> 0 | K31: =(C31-D31)/AE31 -> 0 | L31: =IFERROR((C31-D31)/AE31,0) -> 0 | M31: =D31/$A$2 -> 0 | N31: =O31 -> 0 | O31: =IFERROR(E31/AA31,0) -> 0 | Q31: =MAX((1-ABS((D31-C31)/C31)),0) -> #DIV/0! | S31: =C31*O31 -> 0 | T31: =sumif!E98 -> 0 | U31: =sumif!F98 -> 0 | Y31: 31 | Z31: =AA31 -> -0.57894737 | AA31: =IF(AB31=1,$A$2/Y31,($A$2-AB31)/(Y31-AB31)) -> -0.57894737 | AB31: 12 | AC31: 31 | AD31: =($A$2-(AB31-1))*(C31-D31) -> 0 | AE31: 26 | AP31: =IF(AQ31/G31,AQ31/G31,0) -> #DIV/0! | AQ31: =AVERAGE(AR31:AV31) -> 0 | AR31: 0
A32: Fluorochloridon (25,40) | B32: 120 | C32: 60 | D32: =sumif!C17 -> 0 | E32: =IFERROR(D32/C32,0) -> 0 | F32: =C32/(AC32-AB32+1) -> 3 | G32: =(C32-D32)/(AC32-$A$2) -> 2 | H32: =I32 -> 0 | I32: =sumif!B17 -> 0 | K32: =(C32-D32)/AE32 -> 2.3076923 | L32: =IFERROR((C32-D32)/AE32,0) -> 2.3076923 | M32: =D32/$A$2 -> 0 | N32: =O32 -> 0 | O32: =IFERROR(E32/AA32,0) -> 0 | Q32: =MAX((1-ABS((D32-C32)/C32)),0) -> 0 | S32: =C32*O32 -> 0 | T32: =sumif!E150/1000 -> 0 | U32: =sumif!F150/1000 -> 0 | Y32: 31 | Z32: =AA32 -> -0.57894737 | AA32: =IF(AB32=1,$A$2/Y32,($A$2-AB32)/(Y32-AB32)) -> -0.57894737 | AB32: 12 | AC32: 31 | AD32: =($A$2-(AB32-1))*(C32-D32) -> -600 | AE32: 26 | AI32: 348 | AJ32: =D32 -> 0 | AK32: 156 | AL32: =AI32-AK32 -> 192 | AM32: =SUM(AK32+AJ32)/AI32 -> 0.44827586 | AP32: =IF(AQ32/G32,AQ32/G32,0) -> 0 | AQ32: =AVERAGE(AR32:AV32) -> 0 | AR32: 0
A33: Saflufenacil Tech (25,40) | B33: 1.2 | C33: 2 | D33: =sumif!C25 -> 0 | E33: =IFERROR(D33/C33,0) -> 0 | F33: =C33/(AC33-AB33+1) -> 0.1 | G33: =(C33-D33)/(AC33-$A$2) -> 0.066666667 | H33: =I33 -> 0 | I33: =sumif!B25 -> 0 | K33: =(C33-D33)/AE33 -> 0.076923077 | L33: =IFERROR((C33-D33)/AE33,0) -> 0.076923077 | M33: =D33/$A$2 -> 0 | N33: =O33 -> 0 | O33: =IFERROR(E33/AA33,0) -> 0 | Q33: =MAX((1-ABS((D33-C33)/C33)),0) -> 0 | S33: =C33*O33 -> 0 | T33: =sumif!E211/1000 -> 0 | U33: =sumif!F211/1000 -> 0 | X33: בהתאם להגעת 486 | Y33: 31 | Z33: =AA33 -> -0.57894737 | AA33: =IF(AB33=1,$A$2/Y33,($A$2-AB33)/(Y33-AB33)) -> -0.57894737 | AB33: 12 | AC33: 31 | AD33: =($A$2-(AB33-1))*(C33-D33) -> -20 | AE33: 26 | AP33: =IF(AQ33/G33,AQ33/G33,0) -> 0 | AQ33: =AVERAGE(AR33:AV33) -> 0 | AR33: 0
A34: Pyroxasulfon (41) | D34: =sumif!C4 -> 0 | E34: =IFERROR(D34/C34,0) -> 0 | F34: =C34/(AC34-AB34+1) -> 0 | G34: =(C34-D34)/(AC34-$A$2) -> 0 | H34: =I34 -> 0 | I34: =sumif!B4 -> 0 | K34: =(C34-D34)/AE34 -> 0 | L34: =IFERROR((C34-D34)/AE34,0) -> 0 | M34: =D34/$A$2 -> 0 | N34: =O34 -> 0 | O34: =IFERROR(E34/AA34,0) -> 0 | Q34: =MAX((1-ABS((D34-C34)/C34)),0) -> #DIV/0! | S34: =C34*O34 -> 0 | T34: =sumif!E101 -> 0 | U34: =sumif!F101 -> 0 | Y34: 31 | Z34: =AA34 -> -0.57894737 | AA34: =IF(AB34=1,$A$2/Y34,($A$2-AB34)/(Y34-AB34)) -> -0.57894737 | AB34: 12 | AC34: 31 | AD34: =($A$2-(AB34-1))*(C34-D34) -> 0 | AE34: 26 | AP34: =IF(AQ34/G34,AQ34/G34,0) -> #DIV/0! | AQ34: =AVERAGE(AR34:AV34) -> 0 | AR34: 0
A35: Imazamox (25,40) | B35: 13 | C35: 0 | D35: =sumif!C5 -> 0 | E35: =IFERROR(D35/C35,0) -> 0 | F35: =C35/(AC35-AB35+1) -> 0 | G35: =(C35-D35)/(AC35-$A$2) -> 0 | H35: =I35 -> 0 | I35: =sumif!B5 -> 0 | K35: =(C35-D35)/AE35 -> 0 | L35: =IFERROR((C35-D35)/AE35,0) -> 0 | M35: =D35/$A$2 -> 0 | N35: =O35 -> 0 | O35: =IFERROR(E35/AA35,0) -> 0 | Q35: =MAX((1-ABS((D35-C35)/C35)),0) -> #DIV/0! | S35: =C35*O35 -> 0 | T35: =sumif!E102 -> 0 | U35: =sumif!F102 -> 0 | Y35: 31 | Z35: =AA35 -> -0.57894737 | AA35: =IF(AB35=1,$A$2/Y35,($A$2-AB35)/(Y35-AB35)) -> -0.57894737 | AB35: 12 | AC35: 31 | AD35: =($A$2-(AB35-1))*(C35-D35) -> 0 | AE35: 26 | AP35: =IF(AQ35/G35,AQ35/G35,0) -> #DIV/0! | AQ35: =AVERAGE(AR35:AV35) -> 0 | AR35: 0
A36: Metazachlor (41) | B36: 110 | C36: 110 | D36: =sumif!C23 -> 2.415 | E36: =IFERROR(D36/C36,0) -> 0.021954545 | F36: =C36/(AC36-AB36+1) -> 5.5 | G36: =(C36-D36)/(AC36-$A$2) -> 3.5861667 | H36: =I36 -> 2.415 | I36: =sumif!B23 -> 2.415 | K36: =(C36-D36)/AE36 -> 4.1378846 | L36: =IFERROR((C36-D36)/AE36,0) -> 4.1378846 | M36: =D36/$A$2 -> 2.415 | N36: =O36 -> -0.037921488 | O36: =IFERROR(E36/AA36,0) -> -0.037921488 | Q36: =MAX((1-ABS((D36-C36)/C36)),0) -> 0.021954545 | S36: =C36*O36 -> -4.1713636 | T36: =sumif!E180/1000 -> 0 | U36: =sumif!F180/1000 -> 0 | X36: מחסור של CAC | Y36: 31 | Z36: =AA36 -> -0.57894737 | AA36: =IF(AB36=1,$A$2/Y36,($A$2-AB36)/(Y36-AB36)) -> -0.57894737 | AB36: 12 | AC36: 31 | AD36: =($A$2-(AB36-1))*(C36-D36) -> -1075.85 | AE36: 26 | AI36: 286 | AJ36: =D36 -> 2.415 | AK36: 103 | AL36: =AI36-AK36 -> 183 | AM36: =SUM(AK36+AJ36)/AI36 -> 0.36858392 | AP36: =IF(AQ36/G36,AQ36/G36,0) -> 0.67342102 | AQ36: =AVERAGE(AR36:AV36) -> 2.415 | AR36: 2.415
A37: Thiencarbazone (41) | B37: 4 | C37: 0 | D37: =sumif!C24 -> 0 | E37: =IFERROR(D37/C37,0) -> 0 | F37: =C37/(AC37-AB37+1) -> 0 | G37: =(C37-D37)/(AC37-$A$2) -> 0 | H37: =I37 -> 0 | I37: =sumif!B24 -> 0 | K37: =(C37-D37)/AE37 -> 0 | L37: =IFERROR((C37-D37)/AE37,0) -> 0 | M37: =D37/$A$2 -> 0 | N37: =O37 -> 0 | O37: =IFERROR(E37/AA37,0) -> 0 | Q37: =MAX((1-ABS((D37-C37)/C37)),0) -> #DIV/0! | S37: =C37*O37 -> 0 | X37: מוצר חדש | Y37: 31 | Z37: =AA37 -> -0.57894737 | AA37: =IF(AB37=1,$A$2/Y37,($A$2-AB37)/(Y37-AB37)) -> -0.57894737 | AB37: 12 | AC37: 31 | AD37: =($A$2-(AB37-1))*(C37-D37) -> 0 | AE37: 26 | AP37: =IF(AQ37/G37,AQ37/G37,0) -> #DIV/0! | AQ37: =AVERAGE(AR37:AV37) -> 0 | AR37: 0
A38: Atralone (41) | B38: 40 | C38: 41 | D38: =sumif!C8 -> 1.7 | E38: =IFERROR(D38/C38,0) -> 0.041463415 | F38: =C38/(AC38-AB38+1) -> 2.05 | G38: =(C38-D38)/(AC38-$A$2) -> 1.31 | H38: =I38 -> 1.7 | I38: =sumif!B8 -> 1.7 | K38: =(C38-D38)/AE38 -> 1.5115385 | L38: =IFERROR((C38-D38)/AE38,0) -> 1.5115385 | M38: =D38/$A$2 -> 1.7 | N38: =O38 -> -0.071618625 | O38: =IFERROR(E38/AA38,0) -> -0.071618625 | Q38: =MAX((1-ABS((D38-C38)/C38)),0) -> 0.041463415 | S38: =C38*O38 -> -2.9363636 | T38: =sumif!E100/1000 -> 0 | U38: =sumif!F100/1000 -> 0 | Y38: 31 | Z38: =AA38 -> -0.57894737 | AA38: =IF(AB38=1,$A$2/Y38,($A$2-AB38)/(Y38-AB38)) -> -0.57894737 | AB38: 12 | AC38: 31 | AD38: =($A$2-(AB38-1))*(C38-D38) -> -393 | AE38: 26 | AI38: 96 | AJ38: =D38 -> 1.7 | AK38: 32 | AL38: =AI38-AK38 -> 64 | AM38: =SUM(AK38+AJ38)/AI38 -> 0.35104167 | AP38: =IF(AQ38/G38,AQ38/G38,0) -> 1.2977099 | AQ38: =AVERAGE(AR38:AV38) -> 1.7 | AR38: 1.7
A39: Phenol Oxime (41) | B39: 120 | C39: 0 | D39: =sumif!C26 -> 0 | E39: =IFERROR(D39/C39,0) -> 0 | F39: =C39/(AC39-AB39+1) -> 0 | G39: =(C39-D39)/(AC39-$A$2) -> 0 | H39: =I39 -> 0 | I39: =sumif!B26 -> 0 | K39: =(C39-D39)/AE39 -> 0 | L39: =IFERROR((C39-D39)/AE39,0) -> 0 | M39: =D39/$A$2 -> 0 | N39: =O39 -> 0 | O39: =IFERROR(E39/AA39,0) -> 0 | Q39: =MAX((1-ABS((D39-C39)/C39)),0) -> #DIV/0! | S39: =C39*O39 -> 0 | T39: =sumif!E105 -> 0 | U39: =sumif!F105 -> 0 | Y39: 31 | Z39: =AA39 -> -0.57894737 | AA39: =IF(AB39=1,$A$2/Y39,($A$2-AB39)/(Y39-AB39)) -> -0.57894737 | AB39: 12 | AC39: 31 | AD39: =($A$2-(AB39-1))*(C39-D39) -> 0 | AE39: 26 | AP39: =IF(AQ39/G39,AQ39/G39,0) -> #DIV/0! | AQ39: =AVERAGE(AR39:AV39) -> 0 | AR39: 0
A40: Ethyl HA(41) | C40: 0 | E40: =IFERROR(D40/C40,0) -> 0 | F40: =C40/(AC40-AB40+1) -> 0 | G40: =(C40-D40)/(AC40-$A$2) -> 0 | H40: =I40 -> 0 | K40: =IFERROR((C40-D40)/AE40,0) -> 0 | L40: =IFERROR((C40-D40)/AE40,0) -> 0 | M40: =D40/$A$2 -> 0 | N40: =O40 -> 0 | O40: =IFERROR(E40/AA40,0) -> 0 | Q40: =MAX((1-ABS((D40-C40)/C40)),0) -> #DIV/0! | S40: =C40*O40 -> 0 | T40: =sumif!E106 -> 0 | U40: =sumif!F106 -> 0 | Y40: 31 | Z40: =AA40 -> -0.57894737 | AA40: =IF(AB40=1,$A$2/Y40,($A$2-AB40)/(Y40-AB40)) -> -0.57894737 | AB40: 12 | AC40: 31 | AD40: =($A$2-(AB40-1))*(C40-D40) -> 0 | AE40: 26 | AP40: =IF(AQ40/G40,AQ40/G40,0) -> #DIV/0! | AQ40: =AVERAGE(AR40:AV40) -> #DIV/0!
...

Sheet גיליון להדבקת production
A1: Material | B1: Material description | C1: Batch | D1: Basic start date | E1: Order | F1: Sales Order | G1: Order quantity (GMEIN) | H1: Delivered quantity (GMEIN) | I1: Release date (actual) | J1: Actual finish date | K1: Confirmed Yield Quantity (GMEIN) | L1: Plant | M1: Unit of measure (=GMEIN) | N1: Production line | O1: Storage Location | P1: System Status | Q1: משפחת מוצר/גודל אריזה/מתקן | R1: אריזה | S1: סטטוס מנה | T1: סטטוס מנה ומשפחה | U1: סטטוס מנה ומתקן
A2: 20000007617 | B2: MSRN100+ TFZN30+CYPR45 OD 1000LT | C2: 0000000133 | D2: 46237 | E2: 1390334 | G2: 4000 | H2: 2820 | I2: 46233 | J2: 46235 | K2: 0 | L2: 1401 | M2: L | O2: 1524 | P2: REL CNF PRC BASC BCRQ GMPS ILAS MACM* | Q2: =VLOOKUP(A2,'גיליון דאטה להכל'!A:E,5,0) -> 24F | R2: =VLOOKUP(A2,'לעדכן בסינתזה דאטה אריזה 42+24'!$A:$C,3,0) -> #N/A | S2: =VLOOKUP(#REF!,'מלאי לא תקין'!A:N,17,0) -> #REF! | T2: =_xlfn.CONCAT(S2,Q2) -> #REF! | U2: =_xlfn.CONCAT(S2,O2) -> #REF!
A3: 20000007617 | B3: MSRN100+ TFZN30+CYPR45 OD 1000LT | C3: 0000000135 | D3: 46237 | E3: 1390336 | G3: 4000 | H3: 2550 | I3: 46235 | J3: 46235 | K3: 0 | L3: 1401 | M3: L | O3: 1524 | P3: REL PCNF PRC BASC BCRQ GMPS ILAS MACM* | Q3: =VLOOKUP(A3,'גיליון דאטה להכל'!A:E,5,0) -> 24F | R3: =VLOOKUP(A3,'לעדכן בסינתזה דאטה אריזה 42+24'!$A:$C,3,0) -> #N/A | S3: =VLOOKUP(#REF!,'מלאי לא תקין'!A:N,17,0) -> #REF! | T3: =_xlfn.CONCAT(S3,Q3) -> #REF! | U3: =_xlfn.CONCAT(S3,O3) -> #REF!
A4: 20000007726 | B4: PNDM400 SC PENDIMETHALINE 40SC 1000LT | C4: 0000520621 | D4: 46237 | E4: 1390392 | G4: 7000 | H4: 7000 | I4: 46233 | J4: 46235 | K4: 0 | L4: 1401 | M4: L | O4: 1528 | P4: REL PCNF DLV PRC BASC BCRQ GMPS MACM* | Q4: =VLOOKUP(A4,'גיליון דאטה להכל'!A:E,5,0) -> 28 | R4: =VLOOKUP(A4,'לעדכן בסינתזה דאטה אריזה 42+24'!$A:$C,3,0) -> #N/A | S4: =VLOOKUP(#REF!,'מלאי לא תקין'!A:N,17,0) -> #REF! | T4: =_xlfn.CONCAT(S4,Q4) -> #REF! | U4: =_xlfn.CONCAT(S4,O4) -> #REF!
A5: 50000000053 | B5: DELTA DAMASCONE CRUD 1.00 KG | C5: 0000012952 | D5: 46236 | E5: 1390039 | G5: 6000 | H5: 6858 | I5: 46233 | J5: 46235 | K5: 0 | L5: 1401 | M5: KG | O5: 1141 | P5: REL CNF DLV PRC BASC BCRQ GMPS ILAS* | Q5: =VLOOKUP(A5,'גיליון דאטה להכל'!A:E,5,0) -> שלבי ביניים לא למדידה | R5: =VLOOKUP(A5,'לעדכן בסינתזה דאטה אריזה 42+24'!$A:$C,3,0) -> #N/A | S5: =VLOOKUP(#REF!,'מלאי לא תקין'!A:N,17,0) -> #REF! | T5: =_xlfn.CONCAT(S5,Q5) -> #REF! | U5: =_xlfn.CONCAT(S5,O5) -> #REF!
A6: 30000000097 | B6: MTZC735 TC METAZACHLR T WT CRUD 600 KG | C6: 0000009267 | D6: 46235 | E6: 1389642 | G6: 2800 | H6: 2415 | I6: 46227 | J6: 46235 | K6: 0 | L6: 1401 | M6: KG | O6: 1541 | P6: REL CNF DLV PRC BASC BCRQ GMPS ILAS* | Q6: =VLOOKUP(A6,'גיליון דאטה להכל'!A:E,5,0) -> METAZACHLOR | R6: =VLOOKUP(A6,'לעדכן בסינתזה דאטה אריזה 42+24'!$A:$C,3,0) -> #N/A | S6: =VLOOKUP(#REF!,'מלאי לא תקין'!A:N,17,0) -> #REF! | T6: =_xlfn.CONCAT(S6,Q6) -> #REF! | U6: =_xlfn.CONCAT(S6,O6) -> #REF!
A7: 10000000253 | B7: CLTD120 EC AKODIM 12 200LT MOR 200LT MA | C7: 0000001513 | D7: 46235 | E7: 1390178 | G7: 7200 | H7: 7200 | I7: 46230 | J7: 46235 | K7: 7200 | L7: 1401 | M7: L | O7: 1523 | P7: REL CNF DLV PRC BASC BCRQ GMPS MACM* | Q7: =VLOOKUP(A7,'גיליון דאטה להכל'!A:E,5,0) -> 23 | R7: =VLOOKUP(A7,'לעדכן בסינתזה דאטה אריזה 42+24'!$A:$C,3,0) -> 23 | S7: =VLOOKUP(#REF!,'מלאי לא תקין'!A:N,17,0) -> #REF! | T7: =_xlfn.CONCAT(S7,Q7) -> #REF! | U7: =_xlfn.CONCAT(S7,O7) -> #REF!
A8: 20000000863 | B8: FRXP200 EC FLUROXYPYR 200 SS 200 L | C8: 0000008648 | D8: 46235 | E8: 1390232 | G8: 9600 | H8: 9600 | I8: 46232 | J8: 46235 | K8: 9600 | L8: 1401 | M8: L | O8: 1523 | P8: REL CNF DLV PRC BASC BCRQ GMPS MANC* | Q8: =VLOOKUP(A8,'גיליון דאטה להכל'!A:E,5,0) -> 23 | R8: =VLOOKUP(A8,'לעדכן בסינתזה דאטה אריזה 42+24'!$A:$C,3,0) -> 23 | S8: =VLOOKUP(#REF!,'מלאי לא תקין'!A:N,17,0) -> #REF! | T8: =_xlfn.CONCAT(S8,Q8) -> #REF! | U8: =_xlfn.CONCAT(S8,O8) -> #REF!
A9: 20000007726 | B9: PNDM400 SC PENDIMETHALINE 40SC 1000LT | C9: 0000520622 | D9: 46235 | E9: 1390393 | G9: 8000 | H9: 8000 | I9: 46235 | J9: 46235 | K9: 8000 | L9: 1401 | M9: L | O9: 1528 | P9: REL CNF DLV PRC BASC BCRQ GMPS MANC* | Q9: =VLOOKUP(A9,'גיליון דאטה להכל'!A:E,5,0) -> 28 | R9: =VLOOKUP(A9,'לעדכן בסינתזה דאטה אריזה 42+24'!$A:$C,3,0) -> #N/A | S9: =VLOOKUP(#REF!,'מלאי לא תקין'!A:N,17,0) -> #REF! | T9: =_xlfn.CONCAT(S9,Q9) -> #REF! | U9: =_xlfn.CONCAT(S9,O9) -> #REF!
A10: 20000000183 | B10: CLTD120 EC CLETODIM 120 SS ECO 1000 L | C10: 0000001901 | D10: 46235 | E10: 1390461 | G10: 5000 | H10: 4456 | I10: 46235 | J10: 46235 | K10: 4456 | L10: 1401 | M10: L | O10: 1523 | P10: REL CNF PRC BASC BCRQ GMPS MACM ORRQ* | Q10: =VLOOKUP(A10,'גיליון דאטה להכל'!A:E,5,0) -> 23 | R10: =VLOOKUP(A10,'לעדכן בסינתזה דאטה אריזה 42+24'!$A:$C,3,0) -> 23 | S10: =VLOOKUP(#REF!,'מלאי לא תקין'!A:N,17,0) -> #REF! | T10: =_xlfn.CONCAT(S10,Q10) -> #REF! | U10: =_xlfn.CONCAT(S10,O10) -> #REF!
A11: 20000005837 | B11: CLTN500 SC TOLUREX 50 SC 1000LT | C11: 0000000318 | D11: 46235 | E11: 1390865 | G11: 7000 | H11: 7000 | I11: 46234 | J11: 46235 | K11: 7000 | L11: 1401 | M11: L | O11: 1528 | P11: REL CNF DLV PRC BASC BCRQ GMPS ILAS* | Q11: =VLOOKUP(A11,'גיליון דאטה להכל'!A:E,5,0) -> 28 | R11: =VLOOKUP(A11,'לעדכן בסינתזה דאטה אריזה 42+24'!$A:$C,3,0) -> 28 | S11: =VLOOKUP(#REF!,'מלאי לא תקין'!A:N,17,0) -> #REF! | T11: =_xlfn.CONCAT(S11,Q11) -> #REF! | U11: =_xlfn.CONCAT(S11,O11) -> #REF!
A12: 20000005837 | B12: CLTN500 SC TOLUREX 50 SC 1000LT | C12: 0000000319 | D12: 46235 | E12: 1390866 | G12: 7000 | H12: 7000 | I12: 46234 | J12: 46235 | K12: 7000 | L12: 1401 | M12: L | O12: 1528 | P12: REL CNF DLV PRC BASC BCRQ GMPS ILAS* | Q12: =VLOOKUP(A12,'גיליון דאטה להכל'!A:E,5,0) -> 28 | R12: =VLOOKUP(A12,'לעדכן בסינתזה דאטה אריזה 42+24'!$A:$C,3,0) -> 28 | S12: =VLOOKUP(#REF!,'מלאי לא תקין'!A:N,17,0) -> #REF! | T12: =_xlfn.CONCAT(S12,Q12) -> #REF! | U12: =_xlfn.CONCAT(S12,O12) -> #REF!
A13: 20000005837 | B13: CLTN500 SC TOLUREX 50 SC 1000LT | C13: 0000000320 | D13: 46235 | E13: 1390867 | G13: 7000 | H13: 7000 | I13: 46235 | J13: 46235 | K13: 0 | L13: 1401 | M13: L | O13: 1528 | P13: REL PCNF DLV PRC BASC BCRQ GMPS ILAS* | Q13: =VLOOKUP(A13,'גיליון דאטה להכל'!A:E,5,0) -> 28 | R13: =VLOOKUP(A13,'לעדכן בסינתזה דאטה אריזה 42+24'!$A:$C,3,0) -> 28 | S13: =VLOOKUP(#REF!,'מלאי לא תקין'!A:N,17,0) -> #REF! | T13: =_xlfn.CONCAT(S13,Q13) -> #REF! | U13: =_xlfn.CONCAT(S13,O13) -> #REF!
... A34: 10000011957 | B34: MCPA600 EC ESTER 600 1000LT US | C34: 0000000103 | D34: 46204 | E34: 1390221 | G34: 8000 | H34: 8000 | I34: 46230 | J34: 46235 | K34: 8000 | L34: 1401 | M34: L | O34: 1523 | P34: REL CNF DLV PRC BASC BCRQ GMPS MACM* | Q34: =VLOOKUP(A34,'גיליון דאטה להכל'!A:E,5,0) -> 23 | R34: =VLOOKUP(A34,'לעדכן בסינתזה דאטה אריזה 42+24'!$A:$C,3,0) -> #N/A | S34: =VLOOKUP(#REF!,'מלאי לא תקין'!A:N,17,0) -> #REF! | T34: =_xlfn.CONCAT(S34,Q34) -> #REF! | U34: =_xlfn.CONCAT(S34,O34) -> #REF!
Q35: =VLOOKUP(A35,'גיליון דאטה להכל'!A:E,5,0) -> #N/A | R35: =VLOOKUP(A35,'לעדכן בסינתזה דאטה אריזה 42+24'!$A:$C,3,0) -> #N/A | S35: =VLOOKUP(#REF!,'מלאי לא תקין'!A:N,17,0) -> #REF! | T35: =_xlfn.CONCAT(S35,Q35) -> #REF! | U35: =_xlfn.CONCAT(S35,O35) -> #REF!
Q36: =VLOOKUP(A36,'גיליון דאטה להכל'!A:E,5,0) -> #N/A | R36: =VLOOKUP(A36,'לעדכן בסינתזה דאטה אריזה 42+24'!$A:$C,3,0) -> #N/A | S36: =VLOOKUP(#REF!,'מלאי לא תקין'!A:N,17,0) -> #REF! | T36: =_xlfn.CONCAT(S36,Q36) -> #REF! | U36: =_xlfn.CONCAT(S36,O36) -> #REF!
Q37: =VLOOKUP(A37,'גיליון דאטה להכל'!A:E,5,0) -> #N/A | R37: =VLOOKUP(A37,'לעדכן בסינתזה דאטה אריזה 42+24'!$A:$C,3,0) -> #N/A | S37: =VLOOKUP(#REF!,'מלאי לא תקין'!A:N,17,0) -> #REF! | T37: =_xlfn.CONCAT(S37,Q37) -> #REF! | U37: =_xlfn.CONCAT(S37,O37) -> #REF!
Q38: =VLOOKUP(A38,'גיליון דאטה להכל'!A:E,5,0) -> #N/A | R38: =VLOOKUP(A38,'לעדכן בסינתזה דאטה אריזה 42+24'!$A:$C,3,0) -> #N/A | S38: =VLOOKUP(#REF!,'מלאי לא תקין'!A:N,17,0) -> #REF! | T38: =_xlfn.CONCAT(S38,Q38) -> #REF! | U38: =_xlfn.CONCAT(S38,O38) -> #REF!
Q39: =VLOOKUP(A39,'גיליון דאטה להכל'!A:E,5,0) -> #N/A | R39: =VLOOKUP(A39,'לעדכן בסינתזה דאטה אריזה 42+24'!$A:$C,3,0) -> #N/A | S39: =VLOOKUP(#REF!,'מלאי לא תקין'!A:N,17,0) -> #REF! | T39: =_xlfn.CONCAT(S39,Q39) -> #REF! | U39: =_xlfn.CONCAT(S39,O39) -> #REF!
Q40: =VLOOKUP(A40,'גיליון דאטה להכל'!A:E,5,0) -> #N/A | R40: =VLOOKUP(A40,'לעדכן בסינתזה דאטה אריזה 42+24'!$A:$C,3,0) -> #N/A | S40: =VLOOKUP(#REF!,'מלאי לא תקין'!A:N,17,0) -> #REF! | T40: =_xlfn.CONCAT(S40,Q40) -> #REF! | U40: =_xlfn.CONCAT(S40,O40) -> #REF!
Q41: =VLOOKUP(A41,'גיליון דאטה להכל'!A:E,5,0) -> #N/A | R41: =VLOOKUP(A41,'לעדכן בסינתזה דאטה אריזה 42+24'!$A:$C,3,0) -> #N/A | S41: =VLOOKUP(#REF!,'מלאי לא תקין'!A:N,17,0) -> #REF! | T41: =_xlfn.CONCAT(S41,Q41) -> #REF! | U41: =_xlfn.CONCAT(S41,O41) -> #REF!
Q42: =VLOOKUP(A42,'גיליון דאטה להכל'!A:E,5,0) -> #N/A | R42: =VLOOKUP(A42,'לעדכן בסינתזה דאטה אריזה 42+24'!$A:$C,3,0) -> #N/A | S42: =VLOOKUP(#REF!,'מלאי לא תקין'!A:N,17,0) -> #REF! | T42: =_xlfn.CONCAT(S42,Q42) -> #REF! | U42: =_xlfn.CONCAT(S42,O42) -> #REF!
Q43: =VLOOKUP(A43,'גיליון דאטה להכל'!A:E,5,0) -> #N/A | R43: =VLOOKUP(A43,'לעדכן בסינתזה דאטה אריזה 42+24'!$A:$C,3,0) -> #N/A | S43: =VLOOKUP(#REF!,'מלאי לא תקין'!A:N,17,0) -> #REF! | T43: =_xlfn.CONCAT(S43,Q43) -> #REF! | U43: =_xlfn.CONCAT(S43,O43) -> #REF!
Q44: =VLOOKUP(A44,'גיליון דאטה להכל'!A:E,5,0) -> #N/A | R44: =VLOOKUP(A44,'לעדכן בסינתזה דאטה אריזה 42+24'!$A:$C,3,0) -> #N/A | S44: =VLOOKUP(#REF!,'מלאי לא תקין'!A:N,17,0) -> #REF! | T44: =_xlfn.CONCAT(S44,Q44) -> #REF! | U44: =_xlfn.CONCAT(S44,O44) -> #REF!
Q45: =VLOOKUP(A45,'גיליון דאטה להכל'!A:E,5,0) -> #N/A | R45: =VLOOKUP(A45,'לעדכן בסינתזה דאטה אריזה 42+24'!$A:$C,3,0) -> #N/A | S45: =VLOOKUP(#REF!,'מלאי לא תקין'!A:N,17,0) -> #REF! | T45: =_xlfn.CONCAT(S45,Q45) -> #REF! | U45: =_xlfn.CONCAT(S45,O45) -> #REF!
Q46: =VLOOKUP(A46,'גיליון דאטה להכל'!A:E,5,0) -> #N/A | R46: =VLOOKUP(A46,'לעדכן בסינתזה דאטה אריזה 42+24'!$A:$C,3,0) -> #N/A | S46: =VLOOKUP(#REF!,'מלאי לא תקין'!A:N,17,0) -> #REF! | T46: =_xlfn.CONCAT(S46,Q46) -> #REF! | U46: =_xlfn.CONCAT(S46,O46) -> #REF!
... Q2897: =VLOOKUP(A2897,'גיליון דאטה להכל'!A:E,5,0) -> #N/A | R2897: =VLOOKUP(A2897,'לעדכן בסינתזה דאטה אריזה 42+24'!$A:$C,3,0) -> #N/A | S2897: =VLOOKUP(#REF!,'מלאי לא תקין'!A:N,17,0) -> #REF! | T2897: =_xlfn.CONCAT(S2897,Q2897) -> #REF! | U2897: =_xlfn.CONCAT(S2897,O2897) -> #REF!
Q2898: =VLOOKUP(A2898,'גיליון דאטה להכל'!A:E,5,0) -> #N/A

Sheet גיליון דאטה להכל
A1: Item Code | B1: Res | C1: Type | D1: Family | E1: Segmentation Class | F1: Item Descr | H1: Old Bulk
A2: 30000000358 | B2: 25 | C2: TC | D2: AGANILE | E2: לא מיוצר כרגע | F2: AGANILE 200KG | H2: 27952
A3: 50000000099 | B3: 25 | C3: TC | D3: AGANILE | E3: לא מיוצר כרגע | F3: AGANILE DIST 200.00 KG | H3: 27950
A4: 50000000101 | B4: 25 | C4: TC | D4: AGANILE | E4: לא מיוצר כרגע | F4: AGANILE FLASH 180.00 KG | H4: 27951
A5: 50000000102 | B5: 25 | C5: TC | D5: AGANILE | E5: לא מיוצר כרגע | F5: AGANILE FLASH 200.00 KG | H5: 27951
A6: 50000000040 | B6: 25 | C6: TC | D6: AP | E6: AP 200 | F6: AP200ESTER FLASH AGA 175.00 KG
A7: 30000000315 | B7: 25 | C7: TC | D7: AP | E7: AP 200 | F7: AP 200 DIST AGAN 150 KG | H7: 1917
A8: 10000001567 | B8: 41 | D8: ATRALONE | E8: ATRALONE | F8: ATRL1000 ATRALONE 50KG General | H8: 22205
A9: 10000001566 | B9: 41 | D9: ATRALONE | E9: ATRALONE | F9: ATRL1000 ATRALONE 20KG General | H9: 22205
A10: 10000001248 | B10: 40 | C10: WP | D10: BROMACIL | E10: WP | F10: BRMC800 WP HYBRO 15 KG ECUADOR 15KG EC | H10: 41102
A11: 10000001251 | B11: 40 | C11: WP | D11: BROMACIL | E11: WP | F11: BRMC800 WP BROMACIL 80WP ID LAB 15KG TH | H11: 41102
A12: 20000000900 | B12: 40 | C12: WP | D12: BROMACIL | E12: WP | F12: BRMC800 WP URAGAN 80 WP 500 KG | H12: 41102
A13: 30000000118 | B13: 40 | C13: TC | D13: BROMACIL | E13: BROMACIL | F13: BRMC950 TC URAGAN TECH MIL DUP 15 KG | H13: 41101
A14: 30000000119 | B14: 40 | C14: TC | D14: BROMACIL | E14: BROMACIL | F14: BRMC950 TC BROMACIL TECH 15KG U 15KG US | H14: 41101
A15: 30000000123 | B15: 40 | C15: TC | D15: BROMACIL | E15: BROMACIL | F15: BRMC950 TC URAGAN TECH MIL DUP 525 KG | H15: 41101
A16: 30000000124 | B16: 40 | C16: TC | D16: BROMACIL | E16: BROMACIL | F16: BRMC950 TC AMVA CBROM 525kgMEXI 525KG MX | H16: 41101
A17: 30000005393 | B17: 40 | C17: TC | D17: BROMACIL | E17: BROMACIL | F17: BRMC950 TC URAGAN TECH MIL DUP 420 KG
A18: 30000000125 | B18: 40 | C18: TC | D18: BROMACIL | E18: BROMACIL | F18: BRMC950 TC AMVA CBROM 525KG JP 525KG JP | H18: 41101
A19: 30000000113 | B19: 40 | C19: TC | D19: CHLOROTOLURON | E19: CHLOROTOLURON TOLUREX | F19: CLTN950 TC TOLUREX TECH MILLED 550 KG | H19: 37701
A20: 30000000114 | B20: 40 | C20: TC | D20: CHLOROTOLURON | E20: CHLOROTOLURON TOLUREX | F20: CLTN950 TC CHLOROT.TECH BG EEC 550KG ES | H20: 37701
A21: 30000003588 | B21: 40 | C21: TC | D21: CHLOROTOLURON | E21: CHLOROTOLURON TOLUREX | F21: CLTN950 TC CHLOROT.TECH EEC 550KG JOB ES | H21: 37701
A22: 30000000108 | B22: 40 | C22: TC | D22: CHLOROTOLURON | E22: CHLOROTOLURON TOLUREX | F22: CLTN950 TC TOLUREX TECH MILLED 200 KG | H22: 37701
A23: 30000005593 | B23: 40 | C23: TC | D23: CHLOROTOLURON | E23: CHLOROTOLURON TOLUREX | F23: CLTN950 TC TOLUREX TEC NOT MILLED 550 KG | H23: 37701
A24: 30000000110 | B24: 40 | C24: TC | D24: CHLOROTOLURON | E24: CHLOROTOLURON TOLUREX | F24: CLTN950 TC TOLUREX TECH MILLED 450 KG | H24: 37701
A25: 10000001434 | B25: 41 | D25: DELTA DAMASCON | E25: DELTA DAMASCON | F25: DELTA DAMASCONE 180KG | H25: 11640
A26: 50000000049 | B26: 41 | D26: DELTA DAMASCON | E26: שלבי ביניים לא למדידה | F26: DELTA MTL KTN CR RUS 1.00 KG | H26: 11631
A27: 50000000053 | B27: 41 | D27: DELTA DAMASCON | E27: שלבי ביניים לא למדידה | F27: DELTA DAMASCONE CRUD 1.00 KG | H27: 11636
A28: 50000000056 | B28: 41 | D28: DELTA DAMASCON | E28: שלבי ביניים לא למדידה | F28: DELTA DAMASCON FLASH 1.00 KG | H28: 11638
A29: 10000001433 | B29: 41 | D29: DELTA DAMASCON | E29: DELTA DAMASCON | F29: DELTA DAMASCONE 20KG | H29: 11640
A30: 50000000057 | B30: 41 | D30: DELTA DAMASCON | E30: שלבי ביניים לא למדידה | F30: DELTA DAMASCON FLASH 180.00 KG | H30: 11638
A31: 30000000070 | B31: 40 | C31: TC | D31: DIURON | E31: DIURON | F31: DRON970 TC DIUREX TEC MEXICO 500KG MX | H31: 13751
A32: 30000000071 | B32: 40 | C32: TC | D32: DIURON | E32: DIURON | F32: DRON970 TC DIURON TECH Paint In 500KG IN | H32: 13751
A33: 30000000075 | B33: 40 | C33: TC | D33: DIURON | E33: DIURON | F33: DRON970 TC DIURON TECN OURO FIN 500KG BR | H33: 13751
A34: 30000000076 | B34: 40 | C34: TC | D34: DIURON | E34: DIURON | F34: DRON970 TC DIUREX TECH MILLED 550 KG | H34: 13751
A35: 30000000080 | B35: 40 | C35: TC | D35: DIURON | E35: DIURON | F35: DRON970 TC DIUREX TECH MILLED 650KG BR | H35: 13751
A36: 30000000077 | B36: 40 | C36: TC | D36: DIURON | E36: DIURON | F36: DRON970 TC DIUREX TECH MILLED 600 KG | H36: 13751
A37: 10000000384 | B37: 40 | C37: WP | D37: DIURON | E37: WP | F37: DRON800 WP DIUREX 80 WP 15KG PH | H37: 13804
A38: 10000000385 | B38: 40 | C38: WP | D38: DIURON | E38: WP | F38: DRON800 WP DIUREX 80 WP 15KG LK | H38: 13804
A39: 10000000399 | B39: 40 | C39: WP | D39: DIURON | E39: WP | F39: DRON800 WP KARMEX 80 WP 15KG IN 15KG ID | H39: 13807
A40: 10000001451 | B40: 40 | C40: WP | D40: DIURON | E40: WP | F40: DRON800 WP 15KG General | H40: 13804
...

Sheet גיליון להדבקת Last day
A1: Material | B1: Material description | C1: Batch | D1: Basic start date | E1: Order | F1: Sales Order | G1: Order quantity (GMEIN) | H1: Delivered quantity (GMEIN) | I1: Release date (actual) | J1: Actual finish date | K1: Confirmed Yield Quantity (GMEIN) | L1: Plant | M1: Unit of measure (=GMEIN) | N1: Production line | O1: Storage Location | P1: System Status | Q1: משפחת מוצר/גודל אריזה/מתקן | R1: אריזה | T1: THIENCARBAZONE
A2: 20000007617 | B2: MSRN100+ TFZN30+CYPR45 OD 1000LT | C2: 0000000133 | D2: 46237 | E2: 1390334 | G2: 4000 | H2: 2820 | I2: 46233 | J2: 46235 | K2: 0 | L2: 1401 | M2: L | O2: 1524 | P2: REL CNF PRC BASC BCRQ GMPS ILAS MACM* | Q2: =VLOOKUP(A2,'גיליון דאטה להכל'!A:H,5,0) -> 24F | R2: =VLOOKUP(A2,'לעדכן בסינתזה דאטה אריזה 42+24'!$A:$C,3,0) -> #N/A
